Workbook

Sheet README
A1: APY economics decision-tree and chart data workbook
A2: Purpose | B2: Offline paper/report economics audit. Not an online tool output.
A3: Model framing | B3: Closed-cohort, person-level prevention model. Direct prevented TB cases only; downstream transmission effects are not included.
A4: Cost-saving caveat | B4: Current outputs include testing and preventive treatment costs. Programme setup/running, outreach, travel, staff time, follow-up support, and false-positive incremental costs are zero unless supplied.
A5: Word workflow | B5: Use Editable_Charts for Excel-native charts. Copy charts into Word via Paste Special as Microsoft Excel Chart Object or linked Excel Chart Object.

Sheet Inputs_Assumptions
A1: Input | B1: Value | C1: Units/Source | D1: Status
A2: N | B2: 1500 | C2: people | D2: fixed output setting
A3: screenCoverage | B3: 0.3 | C3: proportion | D3: fixed output setting
A4: screenWindow | B4: 2 | C4: years | D4: fixed output setting
A5: followHorizon | B5: 20 | C5: years | D5: fixed output setting
A6: testType | B6: IGRA | C6: APY setting | D6: fixed output setting
A7: regimen | B7: 3HP | C7: APY setting | D7: fixed output setting
A8: IGRA cost | B8: 113.48 | C8: AUD 2019 KWAB150/Dale-informed | D8: reviewable
A9: TST cost | B9: 116.07 | C9: AUD 2019 KWAB150/Dale-informed | D9: reviewable
A10: 3HP cost | B10: 165.5072 | C10: AUD 2019 KWAB150/Dale-informed | D10: reviewable
A11: 4R cost | B11: 123.3172 | C11: AUD 2019 KWAB150/Dale-informed | D11: reviewable
A12: active TB disease cost per case | B12: 19079.6 | C12: AUD 2019 KWAB150/Dale-informed | D12: reviewable
A13: programme setup cost | B13: 0 | C13: AUD; currently omitted | D13: UNRESOLVED
A14: programme running cost | B14: 0 | C14: AUD; currently omitted | D14: UNRESOLVED
A15: false-positive incremental cost | B15: 0 | C15: AUD/person; currently omitted | D15: UNRESOLVED
A16: active TB disability weight | B16: 0.333 | C16: GBD-style/Dale-informed | D16: reviewable
A17: active TB duration | B17: 0.5 | C17: years | D17: reviewable
A18: TB case fatality risk | B18: 0.074 | C18: configurable assumption | D18: UNRESOLVED
A19: YLL per TB death | B19: 20 | C19: configurable assumption | D19: UNRESOLVED
... A25: WTP threshold high | B25: 75000 | C25: AUD/QALY or AUD/DALY | D25: reviewable

Sheet Strategy_Summary
A1: scenario_id | B1: screeningStrategy | C1: testType | D1: regimen | E1: N | F1: nReps | G1: screenCoverage | H1: screenWindow | I1: followHorizon | J1: nScreened_median | K1: nTotalCoursesStarted_median | L1: nTotalCoursesCompleted_median | M1: nFalsePositiveTreated_median | N1: nCuredInfection_median | O1: nPreventedActiveTB_median | P1: nActiveBy20y_DoNothing_median | Q1: nActiveBy20y_AfterStrategy_median | R1: relativeReduction20y_median | S1: testingCost | T1: treatmentCost | U1: tbDiseaseCostsAverted | V1: totalProgramCost | W1: netCostVsBaseline | X1: tbCasesPrevented | Y1: tbDeathsPrevented | Z1: yldAverted | AA1: yllAverted | AB1: dalysAverted | AC1: qalysGained | AD1: costPerTBCasePrevented | AE1: costPerDALYAverted | AF1: costPerQALYGained | AG1: nmbDALY_45000 | AH1: nmbDALY_75000 | AI1: nmbQALY_45000 | AJ1: nmbQALY_75000 | AK1: dominance_status | AL1: notes
A2: apy_paper_random_igra_3hp | B2: random | C2: IGRA | D2: 3HP | E2: 1500 | F2: 2000 | G2: 0.3 | H2: 2 | I2: 20 | J2: 450.0 | K2: 32.0 | L2: 25.0 | M2: 7.0 | N2: 16.0 | O2: 4.0 | P2: 37.0 | Q2: 33.0 | R2: 0.10526315789473684 | S2: 51066.0 | T2: 5296.2304 | U2: 76318.4 | V2: 56362.2304 | W2: -19956.169599999994 | X2: 4.0 | Y2: 0.296 | Z2: 0.666 | AA2: 5.92 | AB2: 6.586 | AC2: 0.11010794520547931 | AD2: -4989.042399999998 | AE2: -3030.089523231095 | AF2: -181241.86735805977 | AG2: 316326.1696 | AH2: 513906.1696 | AI2: 24911.027134246564 | AJ2: 28214.265490410944 | AK2: dominant_cost_saving | AL2: Direct person-level prevented cases; no downstream transmission effects.
A3: apy_paper_ltbi_igra_3hp | B3: ltbi | C3: IGRA | D3: 3HP | E3: 1500 | F3: 2000 | G3: 0.3 | H3: 2 | I3: 20 | J3: 450.0 | K3: 67.0 | L3: 54.0 | M3: 6.0 | N3: 40.0 | O3: 11.0 | P3: 37.0 | Q3: 26.0 | R3: 0.30434782608695654 | S3: 51066.0 | T3: 11088.9824 | U3: 209875.59999999998 | V3: 62154.9824 | W3: -147720.61759999997 | X3: 11.0 | Y3: 0.814 | Z3: 1.8315000000000001 | AA3: 16.279999999999998 | AB3: 18.1115 | AC3: 0.30277383561643795 | AD3: -13429.147054545452 | AE3: -8156.177986362254 | AF3: -487890.96091888344 | AG3: 962738.1176 | AH3: 1506083.1176 | AI3: 161345.44020273967 | AJ3: 170428.65527123283 | AK3: dominant_cost_saving | AL3: Direct person-level prevented cases; no downstream transmission effects.
A4: apy_paper_cure_igra_3hp | B4: cure | C4: IGRA | D4: 3HP | E4: 1500 | F4: 2000 | G4: 0.3 | H4: 2 | I4: 20 | J4: 450.0 | K4: 67.0 | L4: 54.0 | M4: 6.0 | N4: 40.0 | O4: 11.0 | P4: 37.0 | Q4: 26.0 | R4: 0.2972972972972973 | S4: 51066.0 | T4: 11088.9824 | U4: 209875.59999999998 | V4: 62154.9824 | W4: -147720.61759999997 | X4: 11.0 | Y4: 0.814 | Z4: 1.8315000000000001 | AA4: 16.279999999999998 | AB4: 18.1115 | AC4: 0.30277383561643795 | AD4: -13429.147054545452 | AE4: -8156.177986362254 | AF4: -487890.96091888344 | AG4: 962738.1176 | AH4: 1506083.1176 | AI4: 161345.44020273967 | AJ4: 170428.65527123283 | AK4: dominant_cost_saving | AL4: Direct person-level prevented cases; no downstream transmission effects.
A5: apy_paper_prevent_igra_3hp | B5: prevent | C5: IGRA | D5: 3HP | E5: 1500 | F5: 2000 | G5: 0.3 | H5: 2 | I5: 20 | J5: 450.0 | K5: 62.0 | L5: 50.0 | M5: 6.0 | N5: 37.0 | O5: 12.0 | P5: 37.0 | Q5: 25.0 | R5: 0.3235294117647059 | S5: 51066.0 | T5: 10261.4464 | U5: 228955.19999999998 | V5: 61327.4464 | W5: -167627.7536 | X5: 12.0 | Y5: 0.8879999999999999 | Z5: 1.9980000000000002 | AA5: 17.759999999999998 | AB5: 19.758 | AC5: 0.3303238356164379 | AD5: -13968.979466666666 | AE5: -8484.0446199008 | AF5: -507464.9042118907 | AG5: 1056737.7536 | AH5: 1649477.7536 | AI5: 182492.3262027397 | AJ5: 192402.04127123283 | AK5: dominant_cost_saving | AL5: Direct person-level prevented cases; no downstream transmission effects.

Sheet Cost_Saving_Check
A1: Strategy | B1: Cases prevented | C1: TB disease cost averted | D1: Included programme cost | E1: Testing cost | F1: Treatment cost | G1: Programme setup/running cost | H1: False-positive incremental cost | I1: Net cost vs baseline | J1: Break-even TB cases prevented | K1: Actual minus break-even cases | L1: Cost-saving yes/no | M1: Notes
A2: Random | B2: =Strategy_Summary!Y2 | C2: =B2*Inputs_Assumptions!$B$12 | D2: =E2+F2+G2+H2 | E2: =Strategy_Summary!S2 | F2: =Strategy_Summary!T2 | G2: =Inputs_Assumptions!$B$13+Inputs_Assumptions!$B$14 | H2: =Strategy_Summary!W2-Strategy_Summary!V2+G2 | I2: =D2-C2 | J2: =D2/Inputs_Assumptions!$B$12 | K2: =B2-J2 | L2: =IF(I2<0,"yes","no") | M2: Cost-saving depends on omitted programme costs remaining below the headroom in net cost vs baseline.
A3: LTBI-targeted | B3: =Strategy_Summary!Y3 | C3: =B3*Inputs_Assumptions!$B$12 | D3: =E3+F3+G3+H3 | E3: =Strategy_Summary!S3 | F3: =Strategy_Summary!T3 | G3: =Inputs_Assumptions!$B$13+Inputs_Assumptions!$B$14 | H3: =Strategy_Summary!W3-Strategy_Summary!V3+G3 | I3: =D3-C3 | J3: =D3/Inputs_Assumptions!$B$12 | K3: =B3-J3 | L3: =IF(I3<0,"yes","no") | M3: Cost-saving depends on omitted programme costs remaining below the headroom in net cost vs baseline.
A4: Cure-targeted | B4: =Strategy_Summary!Y4 | C4: =B4*Inputs_Assumptions!$B$12 | D4: =E4+F4+G4+H4 | E4: =Strategy_Summary!S4 | F4: =Strategy_Summary!T4 | G4: =Inputs_Assumptions!$B$13+Inputs_Assumptions!$B$14 | H4: =Strategy_Summary!W4-Strategy_Summary!V4+G4 | I4: =D4-C4 | J4: =D4/Inputs_Assumptions!$B$12 | K4: =B4-J4 | L4: =IF(I4<0,"yes","no") | M4: Cost-saving depends on omitted programme costs remaining below the headroom in net cost vs baseline.
A5: Prevention-targeted | B5: =Strategy_Summary!Y5 | C5: =B5*Inputs_Assumptions!$B$12 | D5: =E5+F5+G5+H5 | E5: =Strategy_Summary!S5 | F5: =Strategy_Summary!T5 | G5: =Inputs_Assumptions!$B$13+Inputs_Assumptions!$B$14 | H5: =Strategy_Summary!W5-Strategy_Summary!V5+G5 | I5: =D5-C5 | J5: =D5/Inputs_Assumptions!$B$12 | K5: =B5-J5 | L5: =IF(I5<0,"yes","no") | M5: Cost-saving depends on omitted programme costs remaining below the headroom in net cost vs baseline.

Sheet Decision_Tree
A1: Strategy | B1: Stage | C1: Branch | D1: Probability / rate | E1: Count | F1: Cost per person | G1: Total cost | H1: Utility / disability input | I1: Health outcome | J1: Notes
A2: Random | B2: Eligible cohort | C2: All | D2: 1 | E2: 1500 | J2: N from APY run setting.
A3: Random | B3: Screened | C3: Screened within window | D3: 0.3 | E3: 450 | F3: 113.48 | G3: 51066 | J3: Derived from nScreened_median / N.
A4: Random | B4: Not screened | C4: Not reached | D4: 0.7 | E4: 1050 | J4: Complement of screened.
A5: Random | B5: TPT started | C5: Started preventive treatment | D5: 0.071111111 | E5: 32 | F5: 165.5072 | G5: 5296.2304 | J5: Derived from courses / screened; includes true and false-positive starts.
A6: Random | B6: TPT completed | C6: Completed preventive treatment | D6: 0.78125 | E6: 25 | J6: Derived from completed / started.
A7: Random | B7: False positive treated | C7: Uninfected/non-active treated | D7: 0.21875 | E7: 7 | F7: 0 | G7: 0 | J7: False-positive incremental cost currently omitted.
A8: Random | B8: ADR stop | C8: Stopped due to ADR | H8: SAE utility 0.8685 | J8: ADR stop count is not in the paper strategy summary CSV; requires model-output extraction if needed.
A9: Random | B9: Partial course | C9: Non-complete partial course | H9: LTBI treatment decrement sensitivity | J9: Partial-course count not in the paper strategy summary CSV; requires model-output extraction if needed.
A10: Random | B10: Infection cured/protected | C10: Cured/protected | D10: 0.5 | E10: 16 | I10: Infections cured/protected | J10: Derived from nCuredInfection_median / courses started.
A11: Random | B11: Active TB case prevented | C11: Prevented direct case | D11: 0.0026666667 | E11: 4 | F11: 19079.6 | G11: 76318.4 | H11: DW 0.333; duration 0.5y | I11: DALYs/QALYs averted | J11: Direct person-level cases prevented; no transmission benefit.
A12: Random | B12: Active TB case not prevented | C12: Residual active TB by horizon | E12: 33 | J12: From nActiveBy20y_AfterStrategy_median.
A13: Random | B13: DALYs averted | C13: Health outcome | H13: DW/YLL assumptions | I13: 6.586 | J13: Includes YLD plus YLL in base case.
A14: Random | B14: QALYs gained | C14: Health outcome | H14: Dale-informed utilities | I14: 0.11010795 | J14: Base case has no LTBI treatment decrement.
A15: Random | B15: Net cost | C15: Economic outcome | G15: -19956.17 | J15: Negative means cost-saving.
A16: Random | B16: ICER per DALY | C16: Economic outcome | I16: -3030.0895 | J16: Negative because net cost is negative.
A17: Random | B17: ICER per QALY | C17: Economic outcome | I17: -181241.87 | J17: Negative because net cost is negative.
A18: LTBI-targeted | B18: Eligible cohort | C18: All | D18: 1 | E18: 1500 | J18: N from APY run setting.
A19: LTBI-targeted | B19: Screened | C19: Screened within window | D19: 0.3 | E19: 450 | F19: 113.48 | G19: 51066 | J19: Derived from nScreened_median / N.
A20: LTBI-targeted | B20: Not screened | C20: Not reached | D20: 0.7 | E20: 1050 | J20: Complement of screened.
A21: LTBI-targeted | B21: TPT started | C21: Started preventive treatment | D21: 0.14888889 | E21: 67 | F21: 165.5072 | G21: 11088.982 | J21: Derived from courses / screened; includes true and false-positive starts.
A22: LTBI-targeted | B22: TPT completed | C22: Completed preventive treatment | D22: 0.80597015 | E22: 54 | J22: Derived from completed / started.
A23: LTBI-targeted | B23: False positive treated | C23: Uninfected/non-active treated | D23: 0.089552239 | E23: 6 | F23: 0 | G23: 0 | J23: False-positive incremental cost currently omitted.
A24: LTBI-targeted | B24: ADR stop | C24: Stopped due to ADR | H24: SAE utility 0.8685 | J24: ADR stop count is not in the paper strategy summary CSV; requires model-output extraction if needed.
A25: LTBI-targeted | B25: Partial course | C25: Non-complete partial course | H25: LTBI treatment decrement sensitivity | J25: Partial-course count not in the paper strategy summary CSV; requires model-output extraction if needed.
A26: LTBI-targeted | B26: Infection cured/protected | C26: Cured/protected | D26: 0.59701493 | E26: 40 | I26: Infections cured/protected | J26: Derived from nCuredInfection_median / courses started.
A27: LTBI-targeted | B27: Active TB case prevented | C27: Prevented direct case | D27: 0.0073333333 | E27: 11 | F27: 19079.6 | G27: 209875.6 | H27: DW 0.333; duration 0.5y | I27: DALYs/QALYs averted | J27: Direct person-level cases prevented; no transmission benefit.
A28: LTBI-targeted | B28: Active TB case not prevented | C28: Residual active TB by horizon | E28: 26 | J28: From nActiveBy20y_AfterStrategy_median.
A29: LTBI-targeted | B29: DALYs averted | C29: Health outcome | H29: DW/YLL assumptions | I29: 18.1115 | J29: Includes YLD plus YLL in base case.
A30: LTBI-targeted | B30: QALYs gained | C30: Health outcome | H30: Dale-informed utilities | I30: 0.30277384 | J30: Base case has no LTBI treatment decrement.
A31: LTBI-targeted | B31: Net cost | C31: Economic outcome | G31: -147720.62 | J31: Negative means cost-saving.
A32: LTBI-targeted | B32: ICER per DALY | C32: Economic outcome | I32: -8156.178 | J32: Negative because net cost is negative.
A33: LTBI-targeted | B33: ICER per QALY | C33: Economic outcome | I33: -487890.96 | J33: Negative because net cost is negative.
A34: Cure-targeted | B34: Eligible cohort | C34: All | D34: 1 | E34: 1500 | J34: N from APY run setting.
A35: Cure-targeted | B35: Screened | C35: Screened within window | D35: 0.3 | E35: 450 | F35: 113.48 | G35: 51066 | J35: Derived from nScreened_median / N.
A36: Cure-targeted | B36: Not screened | C36: Not reached | D36: 0.7 | E36: 1050 | J36: Complement of screened.
A37: Cure-targeted | B37: TPT started | C37: Started preventive treatment | D37: 0.14888889 | E37: 67 | F37: 165.5072 | G37: 11088.982 | J37: Derived from courses / screened; includes true and false-positive starts.
A38: Cure-targeted | B38: TPT completed | C38: Completed preventive treatment | D38: 0.80597015 | E38: 54 | J38: Derived from completed / started.
A39: Cure-targeted | B39: False positive treated | C39: Uninfected/non-active treated | D39: 0.089552239 | E39: 6 | F39: 0 | G39: 0 | J39: False-positive incremental cost currently omitted.
A40: Cure-targeted | B40: ADR stop | C40: Stopped due to ADR | H40: SAE utility 0.8685 | J40: ADR stop count is not in the paper strategy summary CSV; requires model-output extraction if needed.
...

Sheet Sensitivity
A1: scenario_id | B1: screeningStrategy | C1: sensitivity | D1: tbCasesPrevented | E1: dalysAverted | F1: qalysGained | G1: costPerDALYAverted | H1: costPerQALYGained | I1: nmbDALY_45000 | J1: nmbDALY_75000 | K1: nmbQALY_45000 | L1: nmbQALY_75000 | M1: notes | N1: interpretation_changes
A2: apy_paper_random_igra_3hp | B2: random | C2: no_ltbi_treatment_utility_decrement | D2: 4.0 | E2: 6.586 | F2: 0.11010794520547931 | G2: -3030.089523231095 | H2: -181241.86735805977 | I2: 316326.1696 | J2: 513906.1696 | K2: 24911.027134246564 | L2: 28214.265490410944 | M2: Sensitivity assumption; not a final policy setting. | N2: No reversal in generated outputs; magnitude changes only.
A3: apy_paper_random_igra_3hp | B3: random | C3: ltbi_treatment_decrement_0_0133 | D3: 4.0 | E3: 6.586 | F3: 0.0037079452054793183 | G3: -3030.089523231095 | H3: -5382002.293483272 | I3: 316326.1696 | J3: 513906.1696 | K3: 20123.027134246564 | L3: 20234.265490410944 | M3: Sensitivity assumption; not a final policy setting. | N3: No reversal in generated outputs; magnitude changes only.
A4: apy_paper_random_igra_3hp | B4: random | C4: yld_only_no_yll | D4: 4.0 | E4: 0.666 | F4: 0.11010794520547931 | G4: -29964.218618618608 | H4: -181241.86735805977 | I4: 49926.169599999994 | J4: 69906.1696 | K4: 24911.027134246564 | L4: 28214.265490410944 | M4: Sensitivity assumption; not a final policy setting. | N4: No reversal in generated outputs; magnitude changes only.
A5: apy_paper_random_igra_3hp | B5: random | C5: conservative_yll_10 | D5: 4.0 | E5: 3.626 | F5: 0.11010794520547931 | G5: -5503.631991174847 | H5: -181241.86735805977 | I5: 183126.1696 | J5: 291906.1696 | K5: 24911.027134246564 | L5: 28214.265490410944 | M5: Sensitivity assumption; not a final policy setting. | N5: No reversal in generated outputs; magnitude changes only.
A6: apy_paper_random_igra_3hp | B6: random | C6: higher_yll_30 | D6: 4.0 | E6: 9.546 | F6: 0.11010794520547931 | G6: -2090.5268803687404 | H6: -181241.86735805977 | I6: 449526.1696 | J6: 735906.1696 | K6: 24911.027134246564 | L6: 28214.265490410944 | M6: Sensitivity assumption; not a final policy setting. | N6: No reversal in generated outputs; magnitude changes only.
A7: apy_paper_random_igra_3hp | B7: random | C7: lower_tb_case_fatality | D7: 4.0 | E7: 3.626 | F7: 0.11010794520547931 | G7: -5503.631991174847 | H7: -181241.86735805977 | I7: 183126.1696 | J7: 291906.1696 | K7: 24911.027134246564 | L7: 28214.265490410944 | M7: Sensitivity assumption; not a final policy setting. | N7: No reversal in generated outputs; magnitude changes only.
A8: apy_paper_random_igra_3hp | B8: random | C8: higher_tb_case_fatality | D8: 4.0 | E8: 9.546000000000001 | F8: 0.11010794520547931 | G8: -2090.52688036874 | H8: -181241.86735805977 | I8: 449526.1696 | J8: 735906.1696000001 | K8: 24911.027134246564 | L8: 28214.265490410944 | M8: Sensitivity assumption; not a final policy setting. | N8: No reversal in generated outputs; magnitude changes only.
A9: apy_paper_ltbi_igra_3hp | B9: ltbi | C9: no_ltbi_treatment_utility_decrement | D9: 11.0 | E9: 18.1115 | F9: 0.30277383561643795 | G9: -8156.177986362254 | H9: -487890.96091888344 | I9: 962738.1176 | J9: 1506083.1176 | K9: 161345.44020273967 | L9: 170428.65527123283 | M9: Sensitivity assumption; not a final policy setting. | N9: No reversal in generated outputs; magnitude changes only.
A10: apy_paper_ltbi_igra_3hp | B10: ltbi | C10: ltbi_treatment_decrement_0_0133 | D10: 11.0 | E10: 18.1115 | F10: 0.07999883561643795 | G10: -8156.177986362254 | H10: -1846534.595931628 | I10: 962738.1176 | J10: 1506083.1176 | K10: 151320.56520273967 | L10: 153720.53027123283 | M10: Sensitivity assumption; not a final policy setting. | N10: No reversal in generated outputs; magnitude changes only.
A11: apy_paper_ltbi_igra_3hp | B11: ltbi | C11: yld_only_no_yll | D11: 11.0 | E11: 1.8315000000000001 | F11: 0.30277383561643795 | G11: -80655.53786513784 | H11: -487890.96091888344 | I11: 230138.11759999997 | J11: 285083.1176 | K11: 161345.44020273967 | L11: 170428.65527123283 | M11: Sensitivity assumption; not a final policy setting. | N11: No reversal in generated outputs; magnitude changes only.
A12: apy_paper_ltbi_igra_3hp | B12: ltbi | C12: conservative_yll_10 | D12: 11.0 | E12: 9.971499999999999 | F12: 0.30277383561643795 | G12: -14814.28246502532 | H12: -487890.96091888344 | I12: 596438.1175999999 | J12: 895583.1175999999 | K12: 161345.44020273967 | L12: 170428.65527123283 | M12: Sensitivity assumption; not a final policy setting. | N12: No reversal in generated outputs; magnitude changes only.
... A29: apy_paper_prevent_igra_3hp | B29: prevent | C29: higher_tb_case_fatality | D29: 12.0 | E29: 28.638 | F29: 0.3303238356164379 | G29: -5853.333109854039 | H29: -507464.9042118907 | I29: 1456337.7536 | J29: 2315477.7536 | K29: 182492.3262027397 | L29: 192402.04127123283 | M29: Sensitivity assumption; not a final policy setting. | N29: No reversal in generated outputs; magnitude changes only.

Sheet Chart_Data
A1: Strategy | B1: Cost per DALY | C1: Cost per QALY | D1: Net cost | E1: DALYs averted | F1: QALYs gained | G1: Active TB cases prevented
A2: Random | B2: -3030.0895 | C2: -181241.87 | D2: -19956.17 | E2: 6.586 | F2: 0.11010795 | G2: 4
A3: LTBI-targeted | B3: -8156.178 | C3: -487890.96 | D3: -147720.62 | E3: 18.1115 | F3: 0.30277384 | G3: 11
A4: Cure-targeted | B4: -8156.178 | C4: -487890.96 | D4: -147720.62 | E4: 18.1115 | F4: 0.30277384 | G4: 11
A5: Prevention-targeted | B5: -8484.0446 | C5: -507464.9 | D5: -167627.75 | E5: 19.758 | F5: 0.33032384 | G5: 12
A8: Prevention-targeted sensitivity
A9: Sensitivity | B9: Cost per DALY | C9: Cost per QALY | D9: DALYs averted | E9: QALYs gained
A10: no_ltbi_treatment_utility_decrement | B10: -8484.0446 | C10: -507464.9 | D10: 19.758 | E10: 0.33032384
A11: ltbi_treatment_decrement_0_0133 | B11: -8484.0446 | C11: -1349944.2 | D11: 19.758 | E11: 0.12417384
A12: yld_only_no_yll | B12: -83897.775 | C12: -507464.9 | D12: 1.998 | E12: 0.33032384
A13: conservative_yll_10 | B13: -15409.795 | C13: -507464.9 | D13: 10.878 | E13: 0.33032384
A14: higher_yll_30 | B14: -5853.3331 | C14: -507464.9 | D14: 28.638 | E14: 0.33032384
A15: lower_tb_case_fatality | B15: -15409.795 | C15: -507464.9 | D15: 10.878 | E15: 0.33032384
A16: higher_tb_case_fatality | B16: -5853.3331 | C16: -507464.9 | D16: 28.638 | E16: 0.33032384
A19: Cost-saving break-even data
A20: scenario_id | B20: screeningStrategy | C20: active_tb_cases_prevented | D20: tb_disease_costs_averted | E20: current_included_programme_cost | F20: net_cost_vs_baseline | G20: additional_programme_cost_before_no_longer_cost_saving | H20: additional_cost_per_screened_person_before_no_longer_cost_saving | I20: additional_cost_per_tpt_start_before_no_longer_cost_saving
A21: apy_paper_random_igra_3hp | B21: random | C21: 4 | D21: 76318.4 | E21: 56362.23 | F21: -19956.17 | G21: 19956.17 | H21: 44.347044 | I21: 623.6303
A22: apy_paper_ltbi_igra_3hp | B22: ltbi | C22: 11 | D22: 209875.6 | E22: 62154.982 | F22: -147720.62 | G22: 147720.62 | H22: 328.26804 | I22: 2204.7853
A23: apy_paper_cure_igra_3hp | B23: cure | C23: 11 | D23: 209875.6 | E23: 62154.982 | F23: -147720.62 | G23: 147720.62 | H23: 328.26804 | I23: 2204.7853
A24: apy_paper_prevent_igra_3hp | B24: prevent | C24: 12 | D24: 228955.2 | E24: 61327.446 | F24: -167627.75 | G24: 167627.75 | H24: 372.50612 | I24: 2703.6734
A27: Cost-outlay pathway totals
A28: pathway | B28: current_total_cost
A29: screened negative | B29: 113.48
A30: screened positive, does not start TPT | B30: 113.48
A31: screened positive, starts 3HP | B31: 278.9872
A32: false positive treated | B32: 278.9872
A33: true LTBI positive treated | B33: 278.9872
A34: average per person screened | B34: 134.44425
A35: average per TPT course started | B35: 1061.4019

Sheet Editable_Charts
A1: Editable native Excel charts. Copy these into Word using Paste Special as Microsoft Excel Chart Object or Paste Link.

Sheet Cost_Outlay_Definitions
A1: pathway | B1: included_test_cost | C1: result_return_cost | D1: clinical_review_cost | E1: active_tb_exclusion_cost | F1: treatment_course_cost | G1: follow_up_cost | H1: false_positive_incremental_cost | I1: programme_overhead_allocated | J1: current_total_cost | K1: costs_currently_missing | L1: notes
A2: screened negative | B2: 113.48 | F2: 0 | H2: 0 | I2: 0 | J2: 113.48 | K2: result return; clinic visit/clinical review; active TB exclusion/CXR/lab work; travel and outreach; staff time; follow-up support; programme setup/running | L2: Current included cost is the screening test only. Result return and delivery costs are unresolved.
A3: screened positive, does not start TPT | B3: 113.48 | F3: 0 | H3: 0 | I3: 0 | J3: 113.48 | K3: result return; clinic visit/clinical review; active TB exclusion/CXR/lab work; travel and outreach; staff time; follow-up support; programme setup/running | L3: Positive-screen follow-up, clinical review, and active TB exclusion costs are not fully represented.
A4: screened positive, starts 3HP | B4: 113.48 | F4: 165.5072 | H4: 0 | I4: 0 | J4: 278.9872 | K4: result return; clinic visit/clinical review; active TB exclusion/CXR/lab work; travel and outreach; staff time; follow-up support; programme setup/running | L4: Current included cost is test plus 3HP course. Follow-up, support, adherence, and delivery costs are unresolved.
A5: false positive treated | B5: 113.48 | F5: 165.5072 | H5: 0 | I5: 0 | J5: 278.9872 | K5: result return; clinic visit/clinical review; active TB exclusion/CXR/lab work; travel and outreach; staff time; follow-up support; programme setup/running; false-positive incremental management cost | L5: False-positive incremental management cost is currently zero unless supplied separately.
A6: true LTBI positive treated | B6: 113.48 | F6: 165.5072 | H6: 0 | I6: 0 | J6: 278.9872 | K6: result return; clinic visit/clinical review; active TB exclusion/CXR/lab work; travel and outreach; staff time; follow-up support; programme setup/running | L6: Current included cost is test plus 3HP course; care pathway and programme delivery costs remain unresolved.
A7: average per person screened | B7: weighted across strategies | F7: weighted by courses started | H7: 0 | I7: 0 | J7: 134.44425 | K7: result return; clinic visit/clinical review; active TB exclusion/CXR/lab work; travel and outreach; staff time; follow-up support; programme setup/running | L7: Weighted average from current strategy outputs: total included programme cost / total screened.
A8: average per TPT course started | B8: screening costs allocated across starts | F8: weighted by courses started | H8: 0 | I8: 0 | J8: 1061.4019 | K8: result return; clinic visit/clinical review; active TB exclusion/CXR/lab work; travel and outreach; staff time; follow-up support; programme setup/running | L8: Weighted average from current strategy outputs: total included programme cost / total TPT starts.

Sheet Cost_Saving_Break_Even
A1: scenario_id | B1: screeningStrategy | C1: active_tb_cases_prevented | D1: tb_disease_costs_averted | E1: current_included_programme_cost | F1: net_cost_vs_baseline | G1: additional_programme_cost_before_no_longer_cost_saving | H1: additional_cost_per_screened_person_before_no_longer_cost_saving | I1: additional_cost_per_tpt_start_before_no_longer_cost_saving
A2: apy_paper_random_igra_3hp | B2: random | C2: 4 | D2: 76318.4 | E2: 56362.23 | F2: -19956.17 | G2: 19956.17 | H2: 44.347044 | I2: 623.6303
A3: apy_paper_ltbi_igra_3hp | B3: ltbi | C3: 11 | D3: 209875.6 | E3: 62154.982 | F3: -147720.62 | G3: 147720.62 | H3: 328.26804 | I3: 2204.7853
A4: apy_paper_cure_igra_3hp | B4: cure | C4: 11 | D4: 209875.6 | E4: 62154.982 | F4: -147720.62 | G4: 147720.62 | H4: 328.26804 | I4: 2204.7853
A5: apy_paper_prevent_igra_3hp | B5: prevent | C5: 12 | D5: 228955.2 | E5: 61327.446 | F5: -167627.75 | G5: 167627.75 | H5: 372.50612 | I5: 2703.6734
