Workbook

Sheet README
A1: APY economics workbook v5 | B1: Mortality-adjusted QALY update for APY paper/report economics.
A2: Primary QALY output | B2: Dale-compatible mortality-adjusted QALYs: Dale/Bauer active TB morbidity utility decrement plus mortality QALYs.
A3: GBD sensitivity | B3: GBD-aligned mortality-adjusted QALYs use active TB disability weight for morbidity plus the same mortality QALYs.
A4: Excel recalculation | B4: Open in Excel and allow formulas/charts to recalculate.
A5: Model outputs | B5: Imported static APY outputs; rerun APY to change epidemiological/model outputs.

Sheet Inputs_Assumptions
A1: Input | B1: Value | C1: Units/source | D1: Status | E1: Notes
A2: IGRA cost | B2: 113.48 | C2: AUD 2019 | D2: editable
A3: TST cost | B3: 116.07 | C3: AUD 2019 | D3: editable
A4: 3HP cost | B4: 165.5072 | C4: AUD 2019 | D4: editable
A5: 4R cost | B5: 123.3172 | C5: AUD 2019 | D5: editable
A6: active TB disease cost per case | B6: 19079.6 | C6: AUD 2019 | D6: editable
A7: programme setup cost | B7: 0 | C7: AUD total | D7: UNRESOLVED
A8: programme running cost | B8: 0 | C8: AUD total | D8: UNRESOLVED
A9: false-positive incremental cost | B9: 0 | C9: AUD/person | D9: UNRESOLVED
A10: return-for-results cost | B10: 0 | C10: AUD/person screened | D10: UNRESOLVED
A11: clinic review cost | B11: 50 | C11: AUD/TPT start | D11: UNRESOLVED
A12: active TB exclusion / CXR / lab cost | B12: 250 | C12: AUD/TPT start | D12: UNRESOLVED
A13: travel / outreach / staff support cost per screened person | B13: 50 | C13: AUD/person screened | D13: UNRESOLVED
... A22: LTBI treatment utility decrement | B22: 0 | C22: QALY decrement | D22: UNRESOLVED
A23: includeMortalityInQaly | B23: TRUE | C23: boolean | D23: editable | E23: Primary QALYs include mortality when TRUE.
A24: qualityAdjustedLifeExpectancyPerTBDeath | C24: QALYs per TB death | D24: UNRESOLVED | E24: If blank, calculated as YLL per TB death x healthy utility.
A25: qalyActiveTbDurationYears | B25: 0.5 | C25: years | D25: editable
A26: WTP threshold low | B26: 45000 | C26: AUD | D26: editable
A27: WTP threshold high | B27: 75000 | C27: AUD | D27: editable

Sheet Model_Outputs
A1: Strategy_Summary | B1: Imported APY model outputs. To change them, rerun APY and refresh this sheet.
A2: scenario_id | B2: screeningStrategy | C2: testType | D2: regimen | E2: N | F2: nReps | G2: screenCoverage | H2: screenWindow | I2: followHorizon | J2: nScreened_median | K2: nTotalCoursesStarted_median | L2: nTotalCoursesCompleted_median | M2: nFalsePositiveTreated_median | N2: nADRstop_median | O2: nCuredInfection_median | P2: nPreventedActiveTB_median | Q2: nActiveBy20y_DoNothing_median | R2: nActiveBy20y_AfterStrategy_median | S2: relativeReduction20y_median | T2: testingCost | U2: treatmentCost | V2: tbDiseaseCostsAverted | W2: totalProgramCost | X2: netCostVsBaseline | Y2: tbCasesPrevented | Z2: tbDeathsPrevented | AA2: yldAverted | AB2: yllAverted | AC2: dalysAverted | AD2: morbidityOnlyQalysGained | AE2: mortalityQalysGained | AF2: activeTbMorbidityQalysGained_Dale | AG2: activeTbMorbidityQalysGained_GBD | AH2: qalysGained_DaleMortalityAdjusted | AI2: qalysGained_GBDAlignedMortalityAdjusted | AJ2: qalysGained | AK2: costPerTBCasePrevented | AL2: costPerDALYAverted | AM2: costPerQALYGained | AN2: costPerQALYGained_GBDAligned | AO2: nmbDALY_45000 | AP2: nmbDALY_75000 | AQ2: nmbQALY_45000 | AR2: nmbQALY_75000 | AS2: nmbQALY_GBDAligned_45000 | AT2: nmbQALY_GBDAligned_75000 | AU2: dominance_status | AV2: notes
A3: apy_paper_random_igra_3hp | B3: random | C3: IGRA | D3: 3HP | E3: 1500 | F3: 2000 | G3: 0.3 | H3: 2 | I3: 20 | J3: 450 | K3: 32 | L3: 25 | M3: 7 | N3: 1 | O3: 16 | P3: 4 | Q3: 37 | R3: 33 | S3: 0.10526316 | T3: 51066 | U3: 5296.2304 | V3: 76318.4 | W3: 56362.23 | X3: -19956.17 | Y3: 4 | Z3: 0.296 | AA3: 0.666 | AB3: 5.92 | AC3: 6.586 | AD3: 0.11010795 | AE3: 5.169936 | AF3: 0.1102 | AG3: 0.666 | AH3: 5.2800439 | AI3: 5.8358439 | AJ3: 5.2800439 | AK3: -4989.0424 | AL3: -3030.0895 | AM3: -3779.5461 | AN3: -3419.5859 | AO3: 316326.17 | AP3: 513906.17 | AQ3: 257558.15 | AR3: 415959.47 | AS3: 282569.15 | AT3: 457644.47 | AU3: dominant_cost_saving | AV3: Direct person-level prevented cases; no downstream transmission effects.
A4: apy_paper_ltbi_igra_3hp | B4: ltbi | C4: IGRA | D4: 3HP | E4: 1500 | F4: 2000 | G4: 0.3 | H4: 2 | I4: 20 | J4: 450 | K4: 67 | L4: 54 | M4: 6 | N4: 3 | O4: 40 | P4: 11 | Q4: 37 | R4: 26 | S4: 0.30434783 | T4: 51066 | U4: 11088.982 | V4: 209875.6 | W4: 62154.982 | X4: -147720.62 | Y4: 11 | Z4: 0.814 | AA4: 1.8315 | AB4: 16.28 | AC4: 18.1115 | AD4: 0.30277384 | AE4: 14.217324 | AF4: 0.30305 | AG4: 1.8315 | AH4: 14.520098 | AI4: 16.048548 | AJ4: 14.520098 | AK4: -13429.147 | AL4: -8156.178 | AM4: -10173.528 | AN4: -9204.6096 | AO4: 962738.12 | AP4: 1506083.1 | AQ4: 801125.02 | AR4: 1236728 | AS4: 869905.27 | AT4: 1351361.7 | AU4: dominant_cost_saving | AV4: Direct person-level prevented cases; no downstream transmission effects.
A5: apy_paper_cure_igra_3hp | B5: cure | C5: IGRA | D5: 3HP | E5: 1500 | F5: 2000 | G5: 0.3 | H5: 2 | I5: 20 | J5: 450 | K5: 67 | L5: 54 | M5: 6 | N5: 3 | O5: 40 | P5: 11 | Q5: 37 | R5: 26 | S5: 0.2972973 | T5: 51066 | U5: 11088.982 | V5: 209875.6 | W5: 62154.982 | X5: -147720.62 | Y5: 11 | Z5: 0.814 | AA5: 1.8315 | AB5: 16.28 | AC5: 18.1115 | AD5: 0.30277384 | AE5: 14.217324 | AF5: 0.30305 | AG5: 1.8315 | AH5: 14.520098 | AI5: 16.048548 | AJ5: 14.520098 | AK5: -13429.147 | AL5: -8156.178 | AM5: -10173.528 | AN5: -9204.6096 | AO5: 962738.12 | AP5: 1506083.1 | AQ5: 801125.02 | AR5: 1236728 | AS5: 869905.27 | AT5: 1351361.7 | AU5: dominant_cost_saving | AV5: Direct person-level prevented cases; no downstream transmission effects.
A6: apy_paper_prevent_igra_3hp | B6: prevent | C6: IGRA | D6: 3HP | E6: 1500 | F6: 2000 | G6: 0.3 | H6: 2 | I6: 20 | J6: 450 | K6: 62 | L6: 50 | M6: 6 | N6: 3 | O6: 37 | P6: 12 | Q6: 37 | R6: 25 | S6: 0.32352941 | T6: 51066 | U6: 10261.446 | V6: 228955.2 | W6: 61327.446 | X6: -167627.75 | Y6: 12 | Z6: 0.888 | AA6: 1.998 | AB6: 17.76 | AC6: 19.758 | AD6: 0.33032384 | AE6: 15.509808 | AF6: 0.3306 | AG6: 1.998 | AH6: 15.840132 | AI6: 17.507532 | AJ6: 15.840132 | AK6: -13968.979 | AL6: -8484.0446 | AM6: -10582.472 | AN6: -9574.608 | AO6: 1056737.8 | AP6: 1649477.8 | AQ6: 880433.69 | AR6: 1355637.6 | AS6: 955466.69 | AT6: 1480692.6 | AU6: dominant_cost_saving | AV6: Direct person-level prevented cases; no downstream transmission effects.
A9: Health_Outcomes
A10: scenario_id | B10: screeningStrategy | C10: section | D10: metric | E10: value
A11: apy_paper_random_igra_3hp | B11: random | C11: health | D11: tbCasesPrevented | E11: 4
A12: apy_paper_random_igra_3hp | B12: random | C12: health | D12: tbDeathsPrevented | E12: 0.296
A13: apy_paper_random_igra_3hp | B13: random | C13: health | D13: yldAverted | E13: 0.666
A14: apy_paper_random_igra_3hp | B14: random | C14: health | D14: yllAverted | E14: 5.92
A15: apy_paper_random_igra_3hp | B15: random | C15: health | D15: dalysAverted | E15: 6.586
A16: apy_paper_random_igra_3hp | B16: random | C16: health | D16: qualityAdjustedLifeExpectancyPerTBDeath | E16: 17.466
A17: apy_paper_random_igra_3hp | B17: random | C17: health | D17: mortalityQalysGained | E17: 5.169936
A18: apy_paper_random_igra_3hp | B18: random | C18: health | D18: activeTbMorbidityQalysGained_Dale | E18: 0.1102
A19: apy_paper_random_igra_3hp | B19: random | C19: health | D19: activeTbMorbidityQalysGained_GBD | E19: 0.666
A20: apy_paper_random_igra_3hp | B20: random | C20: health | D20: morbidityOnlyQalysGained | E20: 0.11010795
A21: apy_paper_random_igra_3hp | B21: random | C21: health | D21: qalyLossActiveTBAverted | E21: 0.1102
A22: apy_paper_random_igra_3hp | B22: random | C22: health | D22: qalyLossTreatment | E22: 0
... A82: apy_paper_prevent_igra_3hp | B82: prevent | C82: health | D82: qalysGained | E82: 15.840132
A85: Costs
A86: scenario_id | B86: screeningStrategy | C86: section | D86: metric | E86: value
A87: apy_paper_random_igra_3hp | B87: random | C87: costs | D87: testingCost | E87: 51066
A88: apy_paper_random_igra_3hp | B88: random | C88: costs | D88: treatmentCost | E88: 5296.2304
A89: apy_paper_random_igra_3hp | B89: random | C89: costs | D89: falsePositiveIncrementalCost | E89: 0
A90: apy_paper_random_igra_3hp | B90: random | C90: costs | D90: programSetupCost | E90: 0
A91: apy_paper_random_igra_3hp | B91: random | C91: costs | D91: programRunningCost | E91: 0
A92: apy_paper_random_igra_3hp | B92: random | C92: costs | D92: tbDiseaseCostsAverted | E92: 76318.4
A93: apy_paper_random_igra_3hp | B93: random | C93: costs | D93: baselineTBDiseaseCost | E93: 705945.2
A94: apy_paper_random_igra_3hp | B94: random | C94: costs | D94: interventionTBDiseaseCost | E94: 629626.8
A95: apy_paper_random_igra_3hp | B95: random | C95: costs | D95: totalProgramCost | E95: 56362.23
A96: apy_paper_random_igra_3hp | B96: random | C96: costs | D96: netCostVsBaseline | E96: -19956.17
A97: apy_paper_ltbi_igra_3hp | B97: ltbi | C97: costs | D97: testingCost | E97: 51066
A98: apy_paper_ltbi_igra_3hp | B98: ltbi | C98: costs | D98: treatmentCost | E98: 11088.982
... A126: apy_paper_prevent_igra_3hp | B126: prevent | C126: costs | D126: netCostVsBaseline | E126: -167627.75
A129: Sensitivity
A130: scenario_id | B130: screeningStrategy | C130: sensitivity | D130: tbCasesPrevented | E130: dalysAverted | F130: morbidityOnlyQalysGained | G130: mortalityQalysGained | H130: qalysGained | I130: qalysGained_GBDAlignedMortalityAdjusted | J130: costPerDALYAverted | K130: costPerQALYGained | L130: costPerQALYGained_GBDAligned | M130: nmbDALY_45000 | N130: nmbDALY_75000 | O130: nmbQALY_45000 | P130: nmbQALY_75000 | Q130: nmbQALY_GBDAligned_45000 | R130: nmbQALY_GBDAligned_75000 | S130: notes
A131: apy_paper_random_igra_3hp | B131: random | C131: no_ltbi_treatment_utility_decrement | D131: 4 | E131: 6.586 | F131: 0.11010795 | G131: 5.169936 | H131: 5.2800439 | I131: 5.8358439 | J131: -3030.0895 | K131: -3779.5461 | L131: -3419.5859 | M131: 316326.17 | N131: 513906.17 | O131: 257558.15 | P131: 415959.47 | Q131: 282569.15 | R131: 457644.47 | S131: Sensitivity assumption; not a final policy setting.
A132: apy_paper_random_igra_3hp | B132: random | C132: ltbi_treatment_decrement_0_0133 | D132: 4 | E132: 6.586 | F132: 0.0037079452 | G132: 5.169936 | H132: 5.1736439 | I132: 5.7294439 | J132: -3030.0895 | K132: -3857.2754 | L132: -3483.0901 | M132: 316326.17 | N132: 513906.17 | O132: 252770.15 | P132: 407979.47 | Q132: 277781.15 | R132: 449664.47 | S132: Sensitivity assumption; not a final policy setting.
...

Sheet Economic_Calculations
A1: Strategy | B1: testType | C1: regimen | D1: N | E1: nReps | F1: screenCoverage | G1: screenWindow | H1: followHorizon | I1: nScreened | J1: nTotalCoursesStarted | K1: nTotalCoursesCompleted | L1: nFalsePositiveTreated | M1: nADRstop | N1: nCuredInfection | O1: nPreventedActiveTB | P1: nActiveBy20y_DoNothing | Q1: nActiveBy20y_AfterStrategy | R1: relativeReduction20y | S1: testingCost | T1: treatmentCost | U1: falsePositiveIncrementalCost | V1: programmeSetupCost | W1: programmeRunningCost | X1: returnForResultsCost | Y1: clinicReviewCost | Z1: activeTBExclusionCost | AA1: travelOutreachSupportCost | AB1: totalProgramCost | AC1: tbDiseaseCostsAverted | AD1: baselineTBDiseaseCost | AE1: interventionTBDiseaseCost | AF1: netCostVsBaseline | AG1: costPerPersonScreened | AH1: costPerTPTCourseStarted | AI1: costPerTPTCourseCompleted | AJ1: costPerInfectionCured | AK1: costPerTBCasePrevented | AL1: tbDeathsPrevented | AM1: yldAverted | AN1: yllAverted | AO1: dalysAverted | AP1: qualityAdjustedLifeExpectancyPerTBDeath | AQ1: mortalityQalysGained | AR1: activeTbMorbidityQalysGained_Dale | AS1: activeTbMorbidityQalysGained_GBD | AT1: treatmentDecrementQalyLoss | AU1: saeQalyLoss | AV1: morbidityOnlyQalysGained | AW1: qalysGained_DaleMortalityAdjusted | AX1: qalysGained_GBDAlignedMortalityAdjusted | AY1: qalysGained | AZ1: costPerDALYAverted | BA1: costPerQALYGained | BB1: costPerQALYGained_GBDAligned | BC1: nmbDALY_45000 | BD1: nmbDALY_75000 | BE1: nmbQALY_45000 | BF1: nmbQALY_75000 | BG1: nmbQALY_GBDAligned_45000 | BH1: nmbQALY_GBDAligned_75000 | BI1: breakEvenTBCasesPrevented | BJ1: additionalCostMarginBeforeNotCostSaving | BK1: additionalCostPerScreenedBeforeNotCostSaving | BL1: additionalCostPerTPTStartBeforeNotCostSaving
A2: Random | B2: =Model_Outputs!C3 -> IGRA | C2: =Model_Outputs!D3 -> 3HP | D2: =Model_Outputs!E3 -> 1500 | E2: =Model_Outputs!F3 -> 2000 | F2: =Model_Outputs!G3 -> 0.3 | G2: =Model_Outputs!H3 -> 2 | H2: =Model_Outputs!I3 -> 20 | I2: =Model_Outputs!J3 -> 450 | ... R2: =Model_Outputs!S3 -> 0.10526316 | S2: =IFERROR(I2*IF(B2="IGRA",Inputs_Assumptions!$B$2,Inputs_Assumptions!$B$3),"") -> 51066 | T2: =IFERROR(J2*IF(C2="3HP",Inputs_Assumptions!$B$4,IF(C2="4R",Inputs_Assumptions!$B$5,0)),"") -> 5296.2304 | U2: =IFERROR(L2*Inputs_Assumptions!$B$9,"") -> 0 | V2: =Inputs_Assumptions!$B$7 -> 0 | W2: =Inputs_Assumptions!$B$8 -> 0 | X2: =IFERROR(I2*Inputs_Assumptions!$B$10,"") -> 0 | Y2: =IFERROR(J2*Inputs_Assumptions!$B$11,"") -> 1600 | Z2: =IFERROR(J2*Inputs_Assumptions!$B$12,"") -> 8000 | AA2: =IFERROR(I2*Inputs_Assumptions!$B$13,"") -> 22500 | AB2: =SUM(S2:AA2) -> 88462.23 | AC2: =IFERROR(O2*Inputs_Assumptions!$B$6,"") -> 76318.4 | AD2: =IFERROR(P2*Inputs_Assumptions!$B$6,"") -> 705945.2 | AE2: =IFERROR(Q2*Inputs_Assumptions!$B$6,"") -> 629626.8 | AF2: =IFERROR(AB2-AC2,"") -> 12143.83 | AG2: =IFERROR(AB2/I2,"") -> 196.58273 | AH2: =IFERROR(AB2/J2,"") -> 2764.4447 | AI2: =IFERROR(AB2/K2,"") -> 3538.4892 | AJ2: =IFERROR(AF2/N2,"") -> 758.9894 | AK2: =IFERROR(AF2/O2,"") -> 3035.9576 | AL2: =IFERROR(O2*Inputs_Assumptions!$B$16,"") -> 0.296 | AM2: =IFERROR(O2*Inputs_Assumptions!$B$14*Inputs_Assumptions!$B$15,"") -> 0.666 | AN2: =IFERROR(AL2*Inputs_Assumptions!$B$17,"") -> 5.92 | AO2: =IFERROR(AM2+AN2,"") -> 6.586 | AP2: =IF(Inputs_Assumptions!$B$24="",Inputs_Assumptions!$B$17*Inputs_Assumptions!$B$18,Inputs_Assumptions!$B$24) -> 17.466 | AQ2: =IF(Inputs_Assumptions!$B$23,AL2*AP2,0) -> 5.169936 | AR2: =IFERROR(O2*(Inputs_Assumptions!$B$18-Inputs_Assumptions!$B$19)*Inputs_Assumptions!$B$25,"") -> 0.1102 | AS2: =IFERROR(O2*Inputs_Assumptions!$B$14*Inputs_Assumptions!$B$15,"") -> 0.666 | AT2: =IFERROR(J2*Inputs_Assumptions!$B$22*IF(C2="3HP",0.25,IF(C2="4R",4/12,0)),"") -> 0 | AU2: =IFERROR(M2*(Inputs_Assumptions!$B$18-Inputs_Assumptions!$B$20)*Inputs_Assumptions!$B$21,"") -> 9.2054795e-05 | AV2: =IFERROR(AR2-AT2-AU2,"") -> 0.11010795 | AW2: =IFERROR(AR2+AQ2-AT2-AU2,"") -> 5.2800439 | AX2: =IFERROR(AS2+AQ2-AT2-AU2,"") -> 5.8358439 | AY2: =AV2 -> 0.11010795 | AZ2: =IFERROR(AF2/AO2,"") -> 1843.8856 | BA2: =IFERROR(AF2/AV2,"") -> 110290.23 | BB2: =IFERROR(AF2/AW2,"") -> 2299.9487 | BC2: =IFERROR(AO2*Inputs_Assumptions!$B$26-AF2,"") -> 284226.17 | BD2: =IFERROR(AO2*Inputs_Assumptions!$B$27-AF2,"") -> 481806.17 | BE2: =IFERROR(AV2*Inputs_Assumptions!$B$26-AF2,"") -> -7188.9729 | BF2: =IFERROR(AV2*Inputs_Assumptions!$B$27-AF2,"") -> -3885.7345 | BG2: =IFERROR(AW2*Inputs_Assumptions!$B$26-AF2,"") -> 225458.15 | BH2: =IFERROR(AW2*Inputs_Assumptions!$B$27-AF2,"") -> 383859.47 | BI2: =IFERROR(AB2/Inputs_Assumptions!$B$6,"") -> 4.6364824 | BJ2: =IFERROR(IF(AF2<0,-AF2,0),"") -> 0 | BK2: =IFERROR(BJ2/I2,"") -> 0 | BL2: =IFERROR(BJ2/J2,"") -> 0
A3: LTBI-targeted | B3: =Model_Outputs!C4 -> IGRA | C3: =Model_Outputs!D4 -> 3HP | D3: =Model_Outputs!E4 -> 1500 | E3: =Model_Outputs!F4 -> 2000 | F3: =Model_Outputs!G4 -> 0.3 | G3: =Model_Outputs!H4 -> 2 | H3: =Model_Outputs!I4 -> 20 | I3: =Model_Outputs!J4 -> 450 | ... R3: =Model_Outputs!S4 -> 0.30434783 | S3: =IFERROR(I3*IF(B3="IGRA",Inputs_Assumptions!$B$2,Inputs_Assumptions!$B$3),"") -> 51066 | T3: =IFERROR(J3*IF(C3="3HP",Inputs_Assumptions!$B$4,IF(C3="4R",Inputs_Assumptions!$B$5,0)),"") -> 11088.982 | U3: =IFERROR(L3*Inputs_Assumptions!$B$9,"") -> 0 | V3: =Inputs_Assumptions!$B$7 -> 0 | W3: =Inputs_Assumptions!$B$8 -> 0 | X3: =IFERROR(I3*Inputs_Assumptions!$B$10,"") -> 0 | Y3: =IFERROR(J3*Inputs_Assumptions!$B$11,"") -> 3350 | Z3: =IFERROR(J3*Inputs_Assumptions!$B$12,"") -> 16750 | AA3: =IFERROR(I3*Inputs_Assumptions!$B$13,"") -> 22500 | AB3: =SUM(S3:AA3) -> 104754.98 | AC3: =IFERROR(O3*Inputs_Assumptions!$B$6,"") -> 209875.6 | AD3: =IFERROR(P3*Inputs_Assumptions!$B$6,"") -> 705945.2 | AE3: =IFERROR(Q3*Inputs_Assumptions!$B$6,"") -> 496069.6 | AF3: =IFERROR(AB3-AC3,"") -> -105120.62 | AG3: =IFERROR(AB3/I3,"") -> 232.78885 | AH3: =IFERROR(AB3/J3,"") -> 1563.5072 | AI3: =IFERROR(AB3/K3,"") -> 1939.9071 | AJ3: =IFERROR(AF3/N3,"") -> -2628.0154 | AK3: =IFERROR(AF3/O3,"") -> -9556.4198 | AL3: =IFERROR(O3*Inputs_Assumptions!$B$16,"") -> 0.814 | AM3: =IFERROR(O3*Inputs_Assumptions!$B$14*Inputs_Assumptions!$B$15,"") -> 1.8315 | AN3: =IFERROR(AL3*Inputs_Assumptions!$B$17,"") -> 16.28 | AO3: =IFERROR(AM3+AN3,"") -> 18.1115 | AP3: =IF(Inputs_Assumptions!$B$24="",Inputs_Assumptions!$B$17*Inputs_Assumptions!$B$18,Inputs_Assumptions!$B$24) -> 17.466 | AQ3: =IF(Inputs_Assumptions!$B$23,AL3*AP3,0) -> 14.217324 | AR3: =IFERROR(O3*(Inputs_Assumptions!$B$18-Inputs_Assumptions!$B$19)*Inputs_Assumptions!$B$25,"") -> 0.30305 | AS3: =IFERROR(O3*Inputs_Assumptions!$B$14*Inputs_Assumptions!$B$15,"") -> 1.8315 | AT3: =IFERROR(J3*Inputs_Assumptions!$B$22*IF(C3="3HP",0.25,IF(C3="4R",4/12,0)),"") -> 0 | AU3: =IFERROR(M3*(Inputs_Assumptions!$B$18-Inputs_Assumptions!$B$20)*Inputs_Assumptions!$B$21,"") -> 0.00027616438 | AV3: =IFERROR(AR3-AT3-AU3,"") -> 0.30277384 | AW3: =IFERROR(AR3+AQ3-AT3-AU3,"") -> 14.520098 | AX3: =IFERROR(AS3+AQ3-AT3-AU3,"") -> 16.048548 | AY3: =AV3 -> 0.30277384 | AZ3: =IFERROR(AF3/AO3,"") -> -5804.0813 | BA3: =IFERROR(AF3/AV3,"") -> -347191.88 | BB3: =IFERROR(AF3/AW3,"") -> -7239.6632 | BC3: =IFERROR(AO3*Inputs_Assumptions!$B$26-AF3,"") -> 920138.12 | BD3: =IFERROR(AO3*Inputs_Assumptions!$B$27-AF3,"") -> 1463483.1 | BE3: =IFERROR(AV3*Inputs_Assumptions!$B$26-AF3,"") -> 118745.44 | BF3: =IFERROR(AV3*Inputs_Assumptions!$B$27-AF3,"") -> 127828.66 | BG3: =IFERROR(AW3*Inputs_Assumptions!$B$26-AF3,"") -> 758525.02 | BH3: =IFERROR(AW3*Inputs_Assumptions!$B$27-AF3,"") -> 1194128 | BI3: =IFERROR(AB3/Inputs_Assumptions!$B$6,"") -> 5.4904182 | BJ3: =IFERROR(IF(AF3<0,-AF3,0),"") -> 105120.62 | BK3: =IFERROR(BJ3/I3,"") -> 233.60137 | BL3: =IFERROR(BJ3/J3,"") -> 1568.9644
A4: Cure-targeted | B4: =Model_Outputs!C5 -> IGRA | C4: =Model_Outputs!D5 -> 3HP | D4: =Model_Outputs!E5 -> 1500 | E4: =Model_Outputs!F5 -> 2000 | F4: =Model_Outputs!G5 -> 0.3 | G4: =Model_Outputs!H5 -> 2 | H4: =Model_Outputs!I5 -> 20 | I4: =Model_Outputs!J5 -> 450 | ... R4: =Model_Outputs!S5 -> 0.2972973 | S4: =IFERROR(I4*IF(B4="IGRA",Inputs_Assumptions!$B$2,Inputs_Assumptions!$B$3),"") -> 51066 | T4: =IFERROR(J4*IF(C4="3HP",Inputs_Assumptions!$B$4,IF(C4="4R",Inputs_Assumptions!$B$5,0)),"") -> 11088.982 | U4: =IFERROR(L4*Inputs_Assumptions!$B$9,"") -> 0 | V4: =Inputs_Assumptions!$B$7 -> 0 | W4: =Inputs_Assumptions!$B$8 -> 0 | X4: =IFERROR(I4*Inputs_Assumptions!$B$10,"") -> 0 | Y4: =IFERROR(J4*Inputs_Assumptions!$B$11,"") -> 3350 | Z4: =IFERROR(J4*Inputs_Assumptions!$B$12,"") -> 16750 | AA4: =IFERROR(I4*Inputs_Assumptions!$B$13,"") -> 22500 | AB4: =SUM(S4:AA4) -> 104754.98 | AC4: =IFERROR(O4*Inputs_Assumptions!$B$6,"") -> 209875.6 | AD4: =IFERROR(P4*Inputs_Assumptions!$B$6,"") -> 705945.2 | AE4: =IFERROR(Q4*Inputs_Assumptions!$B$6,"") -> 496069.6 | AF4: =IFERROR(AB4-AC4,"") -> -105120.62 | AG4: =IFERROR(AB4/I4,"") -> 232.78885 | AH4: =IFERROR(AB4/J4,"") -> 1563.5072 | AI4: =IFERROR(AB4/K4,"") -> 1939.9071 | AJ4: =IFERROR(AF4/N4,"") -> -2628.0154 | AK4: =IFERROR(AF4/O4,"") -> -9556.4198 | AL4: =IFERROR(O4*Inputs_Assumptions!$B$16,"") -> 0.814 | AM4: =IFERROR(O4*Inputs_Assumptions!$B$14*Inputs_Assumptions!$B$15,"") -> 1.8315 | AN4: =IFERROR(AL4*Inputs_Assumptions!$B$17,"") -> 16.28 | AO4: =IFERROR(AM4+AN4,"") -> 18.1115 | AP4: =IF(Inputs_Assumptions!$B$24="",Inputs_Assumptions!$B$17*Inputs_Assumptions!$B$18,Inputs_Assumptions!$B$24) -> 17.466 | AQ4: =IF(Inputs_Assumptions!$B$23,AL4*AP4,0) -> 14.217324 | AR4: =IFERROR(O4*(Inputs_Assumptions!$B$18-Inputs_Assumptions!$B$19)*Inputs_Assumptions!$B$25,"") -> 0.30305 | AS4: =IFERROR(O4*Inputs_Assumptions!$B$14*Inputs_Assumptions!$B$15,"") -> 1.8315 | AT4: =IFERROR(J4*Inputs_Assumptions!$B$22*IF(C4="3HP",0.25,IF(C4="4R",4/12,0)),"") -> 0 | AU4: =IFERROR(M4*(Inputs_Assumptions!$B$18-Inputs_Assumptions!$B$20)*Inputs_Assumptions!$B$21,"") -> 0.00027616438 | AV4: =IFERROR(AR4-AT4-AU4,"") -> 0.30277384 | AW4: =IFERROR(AR4+AQ4-AT4-AU4,"") -> 14.520098 | AX4: =IFERROR(AS4+AQ4-AT4-AU4,"") -> 16.048548 | AY4: =AV4 -> 0.30277384 | AZ4: =IFERROR(AF4/AO4,"") -> -5804.0813 | BA4: =IFERROR(AF4/AV4,"") -> -347191.88 | BB4: =IFERROR(AF4/AW4,"") -> -7239.6632 | BC4: =IFERROR(AO4*Inputs_Assumptions!$B$26-AF4,"") -> 920138.12 | BD4: =IFERROR(AO4*Inputs_Assumptions!$B$27-AF4,"") -> 1463483.1 | BE4: =IFERROR(AV4*Inputs_Assumptions!$B$26-AF4,"") -> 118745.44 | BF4: =IFERROR(AV4*Inputs_Assumptions!$B$27-AF4,"") -> 127828.66 | BG4: =IFERROR(AW4*Inputs_Assumptions!$B$26-AF4,"") -> 758525.02 | BH4: =IFERROR(AW4*Inputs_Assumptions!$B$27-AF4,"") -> 1194128 | BI4: =IFERROR(AB4/Inputs_Assumptions!$B$6,"") -> 5.4904182 | BJ4: =IFERROR(IF(AF4<0,-AF4,0),"") -> 105120.62 | BK4: =IFERROR(BJ4/I4,"") -> 233.60137 | BL4: =IFERROR(BJ4/J4,"") -> 1568.9644
A5: Prevention-targeted | B5: =Model_Outputs!C6 -> IGRA | C5: =Model_Outputs!D6 -> 3HP | D5: =Model_Outputs!E6 -> 1500 | E5: =Model_Outputs!F6 -> 2000 | F5: =Model_Outputs!G6 -> 0.3 | G5: =Model_Outputs!H6 -> 2 | H5: =Model_Outputs!I6 -> 20 | I5: =Model_Outputs!J6 -> 450 | ... R5: =Model_Outputs!S6 -> 0.32352941 | S5: =IFERROR(I5*IF(B5="IGRA",Inputs_Assumptions!$B$2,Inputs_Assumptions!$B$3),"") -> 51066 | T5: =IFERROR(J5*IF(C5="3HP",Inputs_Assumptions!$B$4,IF(C5="4R",Inputs_Assumptions!$B$5,0)),"") -> 10261.446 | U5: =IFERROR(L5*Inputs_Assumptions!$B$9,"") -> 0 | V5: =Inputs_Assumptions!$B$7 -> 0 | W5: =Inputs_Assumptions!$B$8 -> 0 | X5: =IFERROR(I5*Inputs_Assumptions!$B$10,"") -> 0 | Y5: =IFERROR(J5*Inputs_Assumptions!$B$11,"") -> 3100 | Z5: =IFERROR(J5*Inputs_Assumptions!$B$12,"") -> 15500 | AA5: =IFERROR(I5*Inputs_Assumptions!$B$13,"") -> 22500 | AB5: =SUM(S5:AA5) -> 102427.45 | AC5: =IFERROR(O5*Inputs_Assumptions!$B$6,"") -> 228955.2 | AD5: =IFERROR(P5*Inputs_Assumptions!$B$6,"") -> 705945.2 | AE5: =IFERROR(Q5*Inputs_Assumptions!$B$6,"") -> 476990 | AF5: =IFERROR(AB5-AC5,"") -> -126527.75 | AG5: =IFERROR(AB5/I5,"") -> 227.61655 | AH5: =IFERROR(AB5/J5,"") -> 1652.0556 | AI5: =IFERROR(AB5/K5,"") -> 2048.5489 | AJ5: =IFERROR(AF5/N5,"") -> -3419.669 | AK5: =IFERROR(AF5/O5,"") -> -10543.979 | AL5: =IFERROR(O5*Inputs_Assumptions!$B$16,"") -> 0.888 | AM5: =IFERROR(O5*Inputs_Assumptions!$B$14*Inputs_Assumptions!$B$15,"") -> 1.998 | AN5: =IFERROR(AL5*Inputs_Assumptions!$B$17,"") -> 17.76 | AO5: =IFERROR(AM5+AN5,"") -> 19.758 | AP5: =IF(Inputs_Assumptions!$B$24="",Inputs_Assumptions!$B$17*Inputs_Assumptions!$B$18,Inputs_Assumptions!$B$24) -> 17.466 | AQ5: =IF(Inputs_Assumptions!$B$23,AL5*AP5,0) -> 15.509808 | AR5: =IFERROR(O5*(Inputs_Assumptions!$B$18-Inputs_Assumptions!$B$19)*Inputs_Assumptions!$B$25,"") -> 0.3306 | AS5: =IFERROR(O5*Inputs_Assumptions!$B$14*Inputs_Assumptions!$B$15,"") -> 1.998 | AT5: =IFERROR(J5*Inputs_Assumptions!$B$22*IF(C5="3HP",0.25,IF(C5="4R",4/12,0)),"") -> 0 | AU5: =IFERROR(M5*(Inputs_Assumptions!$B$18-Inputs_Assumptions!$B$20)*Inputs_Assumptions!$B$21,"") -> 0.00027616438 | AV5: =IFERROR(AR5-AT5-AU5,"") -> 0.33032384 | AW5: =IFERROR(AR5+AQ5-AT5-AU5,"") -> 15.840132 | AX5: =IFERROR(AS5+AQ5-AT5-AU5,"") -> 17.507532 | AY5: =AV5 -> 0.33032384 | AZ5: =IFERROR(AF5/AO5,"") -> -6403.8746 | BA5: =IFERROR(AF5/AV5,"") -> -383041.55 | BB5: =IFERROR(AF5/AW5,"") -> -7987.7968 | BC5: =IFERROR(AO5*Inputs_Assumptions!$B$26-AF5,"") -> 1015637.8 | BD5: =IFERROR(AO5*Inputs_Assumptions!$B$27-AF5,"") -> 1608377.8 | BE5: =IFERROR(AV5*Inputs_Assumptions!$B$26-AF5,"") -> 141392.33 | BF5: =IFERROR(AV5*Inputs_Assumptions!$B$27-AF5,"") -> 151302.04 | BG5: =IFERROR(AW5*Inputs_Assumptions!$B$26-AF5,"") -> 839333.69 | BH5: =IFERROR(AW5*Inputs_Assumptions!$B$27-AF5,"") -> 1314537.6 | BI5: =IFERROR(AB5/Inputs_Assumptions!$B$6,"") -> 5.3684273 | BJ5: =IFERROR(IF(AF5<0,-AF5,0),"") -> 126527.75 | BK5: =IFERROR(BJ5/I5,"") -> 281.17279 | BL5: =IFERROR(BJ5/J5,"") -> 2040.7702

Sheet Strategy_Summary
A1: Strategy | B1: TB cases prevented | C1: Net cost vs baseline | D1: DALYs averted | E1: QALYs gained (Dale mortality-adjusted) | F1: GBD-aligned QALYs | G1: Morbidity-only QALYs | H1: Cost per DALY averted | I1: Cost per QALY gained | J1: Cost per active TB case prevented | K1: NMB at AUD 45,000/QALY | L1: NMB at AUD 75,000/QALY | M1: Additional cost margin before not cost-saving | N1: Additional cost per screened person before not cost-saving
A2: =Economic_Calculations!A2 -> Random | B2: =Economic_Calculations!O2 -> 4 | C2: =Economic_Calculations!AF2 -> 12143.83 | D2: =Economic_Calculations!AO2 -> 6.586 | E2: =Economic_Calculations!AV2 -> 0.11010795 | F2: =Economic_Calculations!AW2 -> 5.2800439 | G2: =Economic_Calculations!AU2 -> 9.2054795e-05 | H2: =Economic_Calculations!AX2 -> 5.8358439 | I2: =Economic_Calculations!AY2 -> 0.11010795 | J2: =Economic_Calculations!AK2 -> 3035.9576 | K2: =Economic_Calculations!BE2 -> -7188.9729 | L2: =Economic_Calculations!BF2 -> -3885.7345 | M2: =Economic_Calculations!BJ2 -> 0 | N2: =Economic_Calculations!BK2 -> 0
A3: =Economic_Calculations!A3 -> LTBI-targeted | B3: =Economic_Calculations!O3 -> 11 | C3: =Economic_Calculations!AF3 -> -105120.62 | D3: =Economic_Calculations!AO3 -> 18.1115 | E3: =Economic_Calculations!AV3 -> 0.30277384 | F3: =Economic_Calculations!AW3 -> 14.520098 | G3: =Economic_Calculations!AU3 -> 0.00027616438 | H3: =Economic_Calculations!AX3 -> 16.048548 | I3: =Economic_Calculations!AY3 -> 0.30277384 | J3: =Economic_Calculations!AK3 -> -9556.4198 | K3: =Economic_Calculations!BE3 -> 118745.44 | L3: =Economic_Calculations!BF3 -> 127828.66 | M3: =Economic_Calculations!BJ3 -> 105120.62 | N3: =Economic_Calculations!BK3 -> 233.60137
A4: =Economic_Calculations!A4 -> Cure-targeted | B4: =Economic_Calculations!O4 -> 11 | C4: =Economic_Calculations!AF4 -> -105120.62 | D4: =Economic_Calculations!AO4 -> 18.1115 | E4: =Economic_Calculations!AV4 -> 0.30277384 | F4: =Economic_Calculations!AW4 -> 14.520098 | G4: =Economic_Calculations!AU4 -> 0.00027616438 | H4: =Economic_Calculations!AX4 -> 16.048548 | I4: =Economic_Calculations!AY4 -> 0.30277384 | J4: =Economic_Calculations!AK4 -> -9556.4198 | K4: =Economic_Calculations!BE4 -> 118745.44 | L4: =Economic_Calculations!BF4 -> 127828.66 | M4: =Economic_Calculations!BJ4 -> 105120.62 | N4: =Economic_Calculations!BK4 -> 233.60137
A5: =Economic_Calculations!A5 -> Prevention-targeted | B5: =Economic_Calculations!O5 -> 12 | C5: =Economic_Calculations!AF5 -> -126527.75 | D5: =Economic_Calculations!AO5 -> 19.758 | E5: =Economic_Calculations!AV5 -> 0.33032384 | F5: =Economic_Calculations!AW5 -> 15.840132 | G5: =Economic_Calculations!AU5 -> 0.00027616438 | H5: =Economic_Calculations!AX5 -> 17.507532 | I5: =Economic_Calculations!AY5 -> 0.33032384 | J5: =Economic_Calculations!AK5 -> -10543.979 | K5: =Economic_Calculations!BE5 -> 141392.33 | L5: =Economic_Calculations!BF5 -> 151302.04 | M5: =Economic_Calculations!BJ5 -> 126527.75 | N5: =Economic_Calculations!BK5 -> 281.17279

Sheet DALY_QALY_Source_Audit
A1: scenario_id | B1: screeningStrategy | C1: tbCasesPrevented | D1: dale_bauer_morbidity_qaly_per_tb_case | E1: gbd_aligned_morbidity_qaly_per_tb_case | F1: yld_per_tb_case | G1: yll_per_tb_case | H1: mortality_qalys_per_tb_case | I1: morbidityOnlyQalysGained | J1: total_DaleMortalityAdjusted_QALYs | K1: total_GBDAlignedMortalityAdjusted_QALYs | L1: total_DALYs | M1: daly_to_morbidity_only_qaly_ratio | N1: daly_to_dale_mortality_adjusted_qaly_ratio | O1: daly_to_gbd_aligned_qaly_ratio | P1: costPerQALYGained_GBDAligned
A2: apy_paper_random_igra_3hp | B2: random | C2: 4 | D2: 0.02755 | E2: 0.1665 | F2: 0.1665 | G2: 1.48 | H2: 1.292484 | I2: 0.11010795 | J2: 5.2800439 | K2: 5.8358439 | L2: 6.586 | M2: 59.814031 | N2: 1.2473381 | O2: 1.1285429 | P2: -3419.5859
A3: apy_paper_ltbi_igra_3hp | B3: ltbi | C3: 11 | D3: 0.02755 | E3: 0.1665 | F3: 0.1665 | G3: 1.48 | H3: 1.292484 | I3: 0.30277384 | J3: 14.520098 | K3: 16.048548 | L3: 18.1115 | M3: 59.818577 | N3: 1.2473401 | O3: 1.1285445 | P3: -9204.6096
A4: apy_paper_cure_igra_3hp | B4: cure | C4: 11 | D4: 0.02755 | E4: 0.1665 | F4: 0.1665 | G4: 1.48 | H4: 1.292484 | I4: 0.30277384 | J4: 14.520098 | K4: 16.048548 | L4: 18.1115 | M4: 59.818577 | N4: 1.2473401 | O4: 1.1285445 | P4: -9204.6096
A5: apy_paper_prevent_igra_3hp | B5: prevent | C5: 12 | D5: 0.02755 | E5: 0.1665 | F5: 0.1665 | G5: 1.48 | H5: 1.292484 | I5: 0.33032384 | J5: 15.840132 | K5: 17.507532 | L5: 19.758 | M5: 59.814031 | N5: 1.2473381 | O5: 1.1285429 | P5: -9574.608

Sheet Sensitivity
A1: scenario_id | B1: screeningStrategy | C1: sensitivity | D1: tbCasesPrevented | E1: dalysAverted | F1: morbidityOnlyQalysGained | G1: mortalityQalysGained | H1: qalysGained | I1: qalysGained_GBDAlignedMortalityAdjusted | J1: costPerDALYAverted | K1: costPerQALYGained | L1: costPerQALYGained_GBDAligned | M1: nmbDALY_45000 | N1: nmbDALY_75000 | O1: nmbQALY_45000 | P1: nmbQALY_75000 | Q1: nmbQALY_GBDAligned_45000 | R1: nmbQALY_GBDAligned_75000 | S1: notes
A2: apy_paper_random_igra_3hp | B2: random | C2: no_ltbi_treatment_utility_decrement | D2: 4 | E2: 6.586 | F2: 0.11010795 | G2: 5.169936 | H2: 5.2800439 | I2: 5.8358439 | J2: -3030.0895 | K2: -3779.5461 | L2: -3419.5859 | M2: 316326.17 | N2: 513906.17 | O2: 257558.15 | P2: 415959.47 | Q2: 282569.15 | R2: 457644.47 | S2: Sensitivity assumption; not a final policy setting.
A3: apy_paper_random_igra_3hp | B3: random | C3: ltbi_treatment_decrement_0_0133 | D3: 4 | E3: 6.586 | F3: 0.0037079452 | G3: 5.169936 | H3: 5.1736439 | I3: 5.7294439 | J3: -3030.0895 | K3: -3857.2754 | L3: -3483.0901 | M3: 316326.17 | N3: 513906.17 | O3: 252770.15 | P3: 407979.47 | Q3: 277781.15 | R3: 449664.47 | S3: Sensitivity assumption; not a final policy setting.
A4: apy_paper_random_igra_3hp | B4: random | C4: yld_only_no_yll | D4: 4 | E4: 0.666 | F4: 0.11010795 | G4: 5.169936 | H4: 5.2800439 | I4: 5.8358439 | J4: -29964.219 | K4: -3779.5461 | L4: -3419.5859 | M4: 49926.17 | N4: 69906.17 | O4: 257558.15 | P4: 415959.47 | Q4: 282569.15 | R4: 457644.47 | S4: Sensitivity assumption; not a final policy setting.
A5: apy_paper_random_igra_3hp | B5: random | C5: conservative_yll_10 | D5: 4 | E5: 3.626 | F5: 0.11010795 | G5: 2.584968 | H5: 2.6950759 | I5: 3.2508759 | J5: -5503.632 | K5: -7404.678 | L5: -6138.7054 | M5: 183126.17 | N5: 291906.17 | O5: 141234.59 | P5: 222086.87 | Q5: 166245.59 | R5: 263771.87 | S5: Sensitivity assumption; not a final policy setting.
A6: apy_paper_random_igra_3hp | B6: random | C6: higher_yll_30 | D6: 4 | E6: 9.546 | F6: 0.11010795 | G6: 7.754904 | H6: 7.8650119 | I6: 8.4208119 | J6: -2090.5269 | K6: -2537.3349 | L6: -2369.8629 | M6: 449526.17 | N6: 735906.17 | O6: 373881.71 | P6: 609832.07 | Q6: 398892.71 | R6: 651517.07 | S6: Sensitivity assumption; not a final policy setting.
A7: apy_paper_random_igra_3hp | B7: random | C7: lower_tb_case_fatality | D7: 4 | E7: 3.626 | F7: 0.11010795 | G7: 2.584968 | H7: 2.6950759 | I7: 3.2508759 | J7: -5503.632 | K7: -7404.678 | L7: -6138.7054 | M7: 183126.17 | N7: 291906.17 | O7: 141234.59 | P7: 222086.87 | Q7: 166245.59 | R7: 263771.87 | S7: Sensitivity assumption; not a final policy setting.
A8: apy_paper_random_igra_3hp | B8: random | C8: higher_tb_case_fatality | D8: 4 | E8: 9.546 | F8: 0.11010795 | G8: 7.754904 | H8: 7.8650119 | I8: 8.4208119 | J8: -2090.5269 | K8: -2537.3349 | L8: -2369.8629 | M8: 449526.17 | N8: 735906.17 | O8: 373881.71 | P8: 609832.07 | Q8: 398892.71 | R8: 651517.07 | S8: Sensitivity assumption; not a final policy setting.
A9: apy_paper_ltbi_igra_3hp | B9: ltbi | C9: no_ltbi_treatment_utility_decrement | D9: 11 | E9: 18.1115 | F9: 0.30277384 | G9: 14.217324 | H9: 14.520098 | I9: 16.048548 | J9: -8156.178 | K9: -10173.528 | L9: -9204.6096 | M9: 962738.12 | N9: 1506083.1 | O9: 801125.02 | P9: 1236728 | Q9: 869905.27 | R9: 1351361.7 | S9: Sensitivity assumption; not a final policy setting.
A10: apy_paper_ltbi_igra_3hp | B10: ltbi | C10: ltbi_treatment_decrement_0_0133 | D10: 11 | E10: 18.1115 | F10: 0.079998836 | G10: 14.217324 | H10: 14.297323 | I10: 15.825773 | J10: -8156.178 | K10: -10332.047 | L10: -9334.1803 | M10: 962738.12 | N10: 1506083.1 | O10: 791100.15 | P10: 1220019.8 | Q10: 859880.4 | R10: 1334653.6 | S10: Sensitivity assumption; not a final policy setting.
A11: apy_paper_ltbi_igra_3hp | B11: ltbi | C11: yld_only_no_yll | D11: 11 | E11: 1.8315 | F11: 0.30277384 | G11: 14.217324 | H11: 14.520098 | I11: 16.048548 | J11: -80655.538 | K11: -10173.528 | L11: -9204.6096 | M11: 230138.12 | N11: 285083.12 | O11: 801125.02 | P11: 1236728 | Q11: 869905.27 | R11: 1351361.7 | S11: Sensitivity assumption; not a final policy setting.
A12: apy_paper_ltbi_igra_3hp | B12: ltbi | C12: conservative_yll_10 | D12: 11 | E12: 9.9715 | F12: 0.30277384 | G12: 7.108662 | H12: 7.4114358 | I12: 8.9398858 | J12: -14814.282 | K12: -19931.444 | L12: -16523.77 | M12: 596438.12 | N12: 895583.12 | O12: 481235.23 | P12: 703578.31 | Q12: 550015.48 | R12: 818212.06 | S12: Sensitivity assumption; not a final policy setting.
A13: apy_paper_ltbi_igra_3hp | B13: ltbi | C13: higher_yll_30 | D13: 11 | E13: 26.2515 | F13: 0.30277384 | G13: 21.325986 | H13: 21.62876 | I13: 23.15721 | J13: -5627.1305 | K13: -6829.8237 | L13: -6379.0335 | M13: 1329038.1 | N13: 2116583.1 | O13: 1121014.8 | P13: 1769877.6 | Q13: 1189795.1 | R13: 1884511.4 | S13: Sensitivity assumption; not a final policy setting.
... A29: apy_paper_prevent_igra_3hp | B29: prevent | C29: higher_tb_case_fatality | D29: 12 | E29: 28.638 | F29: 0.33032384 | G29: 23.264712 | H29: 23.595036 | I29: 25.262436 | J29: -5853.3331 | K29: -7104.3653 | L29: -6635.4549 | M29: 1456337.8 | N29: 2315477.8 | O29: 1229404.4 | P29: 1937255.4 | Q29: 1304437.4 | R29: 2062310.4 | S29: Sensitivity assumption; not a final policy setting.

Sheet Mortality_Adjusted_QALY
A1: Strategy | B1: TB cases prevented | C1: Mortality QALYs gained | D1: Dale morbidity QALYs | E1: GBD morbidity QALYs | F1: Dale mortality-adjusted QALYs | G1: GBD-aligned mortality-adjusted QALYs | H1: DALYs | I1: DALY / Dale QALY | J1: DALY / GBD QALY
A2: =Economic_Calculations!A2 -> Random | B2: =Economic_Calculations!O2 -> 4 | C2: =Economic_Calculations!AQ2 -> 5.169936 | D2: =Economic_Calculations!AR2 -> 0.1102 | E2: =Economic_Calculations!AS2 -> 0.666 | F2: =Economic_Calculations!AV2 -> 0.11010795 | G2: =Economic_Calculations!AW2 -> 5.2800439 | H2: =Economic_Calculations!AO2 -> 6.586 | I2: =IFERROR(H2/F2,"") -> 59.814031 | J2: =IFERROR(H2/G2,"") -> 1.2473381
A3: =Economic_Calculations!A3 -> LTBI-targeted | B3: =Economic_Calculations!O3 -> 11 | C3: =Economic_Calculations!AQ3 -> 14.217324 | D3: =Economic_Calculations!AR3 -> 0.30305 | E3: =Economic_Calculations!AS3 -> 1.8315 | F3: =Economic_Calculations!AV3 -> 0.30277384 | G3: =Economic_Calculations!AW3 -> 14.520098 | H3: =Economic_Calculations!AO3 -> 18.1115 | I3: =IFERROR(H3/F3,"") -> 59.818577 | J3: =IFERROR(H3/G3,"") -> 1.2473401
A4: =Economic_Calculations!A4 -> Cure-targeted | B4: =Economic_Calculations!O4 -> 11 | C4: =Economic_Calculations!AQ4 -> 14.217324 | D4: =Economic_Calculations!AR4 -> 0.30305 | E4: =Economic_Calculations!AS4 -> 1.8315 | F4: =Economic_Calculations!AV4 -> 0.30277384 | G4: =Economic_Calculations!AW4 -> 14.520098 | H4: =Economic_Calculations!AO4 -> 18.1115 | I4: =IFERROR(H4/F4,"") -> 59.818577 | J4: =IFERROR(H4/G4,"") -> 1.2473401
A5: =Economic_Calculations!A5 -> Prevention-targeted | B5: =Economic_Calculations!O5 -> 12 | C5: =Economic_Calculations!AQ5 -> 15.509808 | D5: =Economic_Calculations!AR5 -> 0.3306 | E5: =Economic_Calculations!AS5 -> 1.998 | F5: =Economic_Calculations!AV5 -> 0.33032384 | G5: =Economic_Calculations!AW5 -> 15.840132 | H5: =Economic_Calculations!AO5 -> 19.758 | I5: =IFERROR(H5/F5,"") -> 59.814031 | J5: =IFERROR(H5/G5,"") -> 1.2473381

Sheet Chart_Data
A1: Strategy | B1: DALYs averted | C1: QALYs gained (Dale mortality-adjusted) | D1: GBD-aligned QALYs | E1: Net cost vs baseline | F1: Cost per DALY | G1: Cost per QALY | H1: Cost per GBD-aligned QALY | I1: TB cases prevented | J1: Additional cost margin
A2: =Strategy_Summary!A2 -> Random | B2: =Strategy_Summary!D2 -> 6.586 | C2: =Strategy_Summary!E2 -> 0.11010795 | D2: =Strategy_Summary!F2 -> 5.2800439 | E2: =Strategy_Summary!C2 -> 12143.83 | F2: =Strategy_Summary!H2 -> 5.8358439 | G2: =Strategy_Summary!I2 -> 0.11010795 | H2: =Economic_Calculations!AZ2 -> 1843.8856 | I2: =Strategy_Summary!B2 -> 4 | J2: =Strategy_Summary!M2 -> 0
A3: =Strategy_Summary!A3 -> LTBI-targeted | B3: =Strategy_Summary!D3 -> 18.1115 | C3: =Strategy_Summary!E3 -> 0.30277384 | D3: =Strategy_Summary!F3 -> 14.520098 | E3: =Strategy_Summary!C3 -> -105120.62 | F3: =Strategy_Summary!H3 -> 16.048548 | G3: =Strategy_Summary!I3 -> 0.30277384 | H3: =Economic_Calculations!AZ3 -> -5804.0813 | I3: =Strategy_Summary!B3 -> 11 | J3: =Strategy_Summary!M3 -> 105120.62
A4: =Strategy_Summary!A4 -> Cure-targeted | B4: =Strategy_Summary!D4 -> 18.1115 | C4: =Strategy_Summary!E4 -> 0.30277384 | D4: =Strategy_Summary!F4 -> 14.520098 | E4: =Strategy_Summary!C4 -> -105120.62 | F4: =Strategy_Summary!H4 -> 16.048548 | G4: =Strategy_Summary!I4 -> 0.30277384 | H4: =Economic_Calculations!AZ4 -> -5804.0813 | I4: =Strategy_Summary!B4 -> 11 | J4: =Strategy_Summary!M4 -> 105120.62
A5: =Strategy_Summary!A5 -> Prevention-targeted | B5: =Strategy_Summary!D5 -> 19.758 | C5: =Strategy_Summary!E5 -> 0.33032384 | D5: =Strategy_Summary!F5 -> 15.840132 | E5: =Strategy_Summary!C5 -> -126527.75 | F5: =Strategy_Summary!H5 -> 17.507532 | G5: =Strategy_Summary!I5 -> 0.33032384 | H5: =Economic_Calculations!AZ5 -> -6403.8746 | I5: =Strategy_Summary!B5 -> 12 | J5: =Strategy_Summary!M5 -> 126527.75

Sheet Editable_Charts
A1: Editable native Excel charts. Primary QALY charts use Dale-compatible mortality-adjusted QALYs.

Sheet Formula_Audit
A1: Audit item | B1: Check/source | C1: Notes
A2: Strategy_Summary formula linked | B2: =_xludf.ISFORMULA(Strategy_Summary!B2) -> #NAME? | C2: TRUE expected
A3: Chart_Data formula linked | B3: =_xludf.ISFORMULA(Chart_Data!B2) -> #NAME? | C3: TRUE expected
A4: Primary QALY includes mortality | B4: Economic_Calculations!AV: qalysGained_DaleMortalityAdjusted | C4: Primary QALY charts use this field
A5: GBD sensitivity present | B5: Economic_Calculations!AW and DALY_QALY_Source_Audit | C5: GBD-aligned morbidity sensitivity
A6: Model outputs requiring rerun | B6: screening, prevalence, treatment pathway, cases prevented | C6: Excel does not recreate stochastic ABM
