Workbook

Sheet README
A1: APY economics formula-linked workbook | B1: Live audit layer for paper/report economics.
A2: Input workbook inspected | B2: C:\Users\emmas\Documents\GITHUB\tb-community-risk\APY_economics_decision_tree_and_editable_charts_v2.xlsx
A3: Strategy_Summary in input | B3: 0 formula cells; 54 non-empty cells.
A4: Chart_Data in input | B4: 0 formula cells; 137 non-empty cells.
A5: Model_Outputs | B5: Static APY stochastic model outputs imported from CSV. Do not edit unless refreshing after an APY rerun.
A6: Inputs_Assumptions | B6: Live editable assumptions. Changing costs, utilities, DALY/QALY inputs, and WTP thresholds updates economics and charts.
A7: Requires APY rerun | B7: Changing screening strategy, prevalence/risk inputs, treatment start probability, treatment effects, screened counts, TPT starts/completions, infections cured, or cases prevented requires rerunning APY and refreshing Model_Outputs.
A8: Excel recalculation | B8: Open the workbook in Excel and allow formulas to recalculate. Python writes formulas but does not evaluate final displayed values.
A9: Scope | B9: Excel is an audit/calculation layer, not the stochastic ABM.
A10: Chart fix v3 | B10: Charts were rebuilt from formula-linked Chart_Data. Scatter charts use one visible marker series per strategy with plain-text strategy names.
A11: Excel recalculation | B11: Open this workbook in Excel and allow recalculation. Chart values update when Inputs_Assumptions change.

Sheet Inputs_Assumptions
A1: Input | B1: Value | C1: Units/source | D1: Status | E1: Notes
A2: IGRA cost | B2: 113.48 | C2: AUD 2019 | D2: editable | E2: Screening test unit cost.
A3: TST cost | B3: 116.07 | C3: AUD 2019 | D3: editable | E3: Alternative screening test unit cost.
A4: 3HP cost | B4: 165.5072 | C4: AUD 2019 | D4: editable | E4: Preventive treatment course cost.
A5: 4R cost | B5: 123.3172 | C5: AUD 2019 | D5: editable | E5: Preventive treatment course cost.
A6: active TB disease cost per case | B6: 19079.6 | C6: AUD 2019 | D6: editable | E6: Disease cost averted per active TB case prevented.
A7: programme setup cost | B7: 1000000 | C7: AUD total | D7: UNRESOLVED | E7: Currently zero unless local programme costs are supplied.
A8: programme running cost | B8: 0 | C8: AUD total | D8: UNRESOLVED | E8: Currently zero unless local programme costs are supplied.
A9: false-positive incremental cost | B9: 0 | C9: AUD/person | D9: UNRESOLVED | E9: Additional management cost per false-positive treatment course.
A10: return-for-results cost | B10: 0 | C10: AUD/person screened | D10: UNRESOLVED | E10: Result return and communication cost.
A11: clinic review cost | B11: 0 | C11: AUD/TPT start | D11: UNRESOLVED | E11: Clinical review cost for positive or treated participants.
A12: active TB exclusion / CXR / lab cost | B12: 0 | C12: AUD/TPT start | D12: UNRESOLVED | E12: Active TB exclusion work-up cost.
A13: travel / outreach / staff support cost per screened person | B13: 0 | C13: AUD/person screened | D13: UNRESOLVED | E13: Travel, outreach, staff time, and follow-up support allocation.
... A24: WTP threshold high | B24: 75000 | C24: AUD/QALY or AUD/DALY | D24: editable | E24: High willingness-to-pay threshold.

Sheet Model_Outputs
A1: Strategy_Summary | B1: These values are imported APY model outputs. To change them, rerun the APY model and refresh this sheet.
A2: scenario_id | B2: screeningStrategy | C2: testType | D2: regimen | E2: N | F2: nReps | G2: screenCoverage | H2: screenWindow | I2: followHorizon | J2: nScreened_median | K2: nTotalCoursesStarted_median | L2: nTotalCoursesCompleted_median | M2: nFalsePositiveTreated_median | N2: nCuredInfection_median | O2: nPreventedActiveTB_median | P2: nActiveBy20y_DoNothing_median | Q2: nActiveBy20y_AfterStrategy_median | R2: relativeReduction20y_median | S2: testingCost | T2: treatmentCost | U2: tbDiseaseCostsAverted | V2: totalProgramCost | W2: netCostVsBaseline | X2: tbCasesPrevented | Y2: tbDeathsPrevented | Z2: yldAverted | AA2: yllAverted | AB2: dalysAverted | AC2: qalysGained | AD2: costPerTBCasePrevented | AE2: costPerDALYAverted | AF2: costPerQALYGained | AG2: nmbDALY_45000 | AH2: nmbDALY_75000 | AI2: nmbQALY_45000 | AJ2: nmbQALY_75000 | AK2: dominance_status | AL2: notes
A3: apy_paper_random_igra_3hp | B3: random | C3: IGRA | D3: 3HP | E3: 1500 | F3: 2000 | G3: 0.3 | H3: 2 | I3: 20 | J3: 450 | K3: 32 | L3: 25 | M3: 7 | N3: 16 | O3: 4 | P3: 37 | Q3: 33 | R3: 0.10526316 | S3: 51066 | T3: 5296.2304 | U3: 76318.4 | V3: 56362.23 | W3: -19956.17 | X3: 4 | Y3: 0.296 | Z3: 0.666 | AA3: 5.92 | AB3: 6.586 | AC3: 0.11010795 | AD3: -4989.0424 | AE3: -3030.0895 | AF3: -181241.87 | AG3: 316326.17 | AH3: 513906.17 | AI3: 24911.027 | AJ3: 28214.265 | AK3: dominant_cost_saving | AL3: Direct person-level prevented cases; no downstream transmission effects.
A4: apy_paper_ltbi_igra_3hp | B4: ltbi | C4: IGRA | D4: 3HP | E4: 1500 | F4: 2000 | G4: 0.3 | H4: 2 | I4: 20 | J4: 450 | K4: 67 | L4: 54 | M4: 6 | N4: 40 | O4: 11 | P4: 37 | Q4: 26 | R4: 0.30434783 | S4: 51066 | T4: 11088.982 | U4: 209875.6 | V4: 62154.982 | W4: -147720.62 | X4: 11 | Y4: 0.814 | Z4: 1.8315 | AA4: 16.28 | AB4: 18.1115 | AC4: 0.30277384 | AD4: -13429.147 | AE4: -8156.178 | AF4: -487890.96 | AG4: 962738.12 | AH4: 1506083.1 | AI4: 161345.44 | AJ4: 170428.66 | AK4: dominant_cost_saving | AL4: Direct person-level prevented cases; no downstream transmission effects.
A5: apy_paper_cure_igra_3hp | B5: cure | C5: IGRA | D5: 3HP | E5: 1500 | F5: 2000 | G5: 0.3 | H5: 2 | I5: 20 | J5: 450 | K5: 67 | L5: 54 | M5: 6 | N5: 40 | O5: 11 | P5: 37 | Q5: 26 | R5: 0.2972973 | S5: 51066 | T5: 11088.982 | U5: 209875.6 | V5: 62154.982 | W5: -147720.62 | X5: 11 | Y5: 0.814 | Z5: 1.8315 | AA5: 16.28 | AB5: 18.1115 | AC5: 0.30277384 | AD5: -13429.147 | AE5: -8156.178 | AF5: -487890.96 | AG5: 962738.12 | AH5: 1506083.1 | AI5: 161345.44 | AJ5: 170428.66 | AK5: dominant_cost_saving | AL5: Direct person-level prevented cases; no downstream transmission effects.
A6: apy_paper_prevent_igra_3hp | B6: prevent | C6: IGRA | D6: 3HP | E6: 1500 | F6: 2000 | G6: 0.3 | H6: 2 | I6: 20 | J6: 450 | K6: 62 | L6: 50 | M6: 6 | N6: 37 | O6: 12 | P6: 37 | Q6: 25 | R6: 0.32352941 | S6: 51066 | T6: 10261.446 | U6: 228955.2 | V6: 61327.446 | W6: -167627.75 | X6: 12 | Y6: 0.888 | Z6: 1.998 | AA6: 17.76 | AB6: 19.758 | AC6: 0.33032384 | AD6: -13968.979 | AE6: -8484.0446 | AF6: -507464.9 | AG6: 1056737.8 | AH6: 1649477.8 | AI6: 182492.33 | AJ6: 192402.04 | AK6: dominant_cost_saving | AL6: Direct person-level prevented cases; no downstream transmission effects.
A9: Health_Outcomes
A10: scenario_id | B10: screeningStrategy | C10: section | D10: metric | E10: value
A11: apy_paper_random_igra_3hp | B11: random | C11: health | D11: tbCasesPrevented | E11: 4
A12: apy_paper_random_igra_3hp | B12: random | C12: health | D12: tbDeathsPrevented | E12: 0.296
A13: apy_paper_random_igra_3hp | B13: random | C13: health | D13: yldAverted | E13: 0.666
A14: apy_paper_random_igra_3hp | B14: random | C14: health | D14: yllAverted | E14: 5.92
A15: apy_paper_random_igra_3hp | B15: random | C15: health | D15: dalysAverted | E15: 6.586
A16: apy_paper_random_igra_3hp | B16: random | C16: health | D16: qalyLossActiveTBAverted | E16: 0.1102
A17: apy_paper_random_igra_3hp | B17: random | C17: health | D17: qalyLossTreatment | E17: 0
A18: apy_paper_random_igra_3hp | B18: random | C18: health | D18: qalyLossSAE | E18: 9.2054795e-05
A19: apy_paper_random_igra_3hp | B19: random | C19: health | D19: qalysGained | E19: 0.11010795
A20: apy_paper_ltbi_igra_3hp | B20: ltbi | C20: health | D20: tbCasesPrevented | E20: 11
A21: apy_paper_ltbi_igra_3hp | B21: ltbi | C21: health | D21: tbDeathsPrevented | E21: 0.814
A22: apy_paper_ltbi_igra_3hp | B22: ltbi | C22: health | D22: yldAverted | E22: 1.8315
... A46: apy_paper_prevent_igra_3hp | B46: prevent | C46: health | D46: qalysGained | E46: 0.33032384
A49: Costs
A50: scenario_id | B50: screeningStrategy | C50: section | D50: metric | E50: value
A51: apy_paper_random_igra_3hp | B51: random | C51: costs | D51: testingCost | E51: 51066
A52: apy_paper_random_igra_3hp | B52: random | C52: costs | D52: treatmentCost | E52: 5296.2304
A53: apy_paper_random_igra_3hp | B53: random | C53: costs | D53: falsePositiveIncrementalCost | E53: 0
A54: apy_paper_random_igra_3hp | B54: random | C54: costs | D54: programSetupCost | E54: 0
A55: apy_paper_random_igra_3hp | B55: random | C55: costs | D55: programRunningCost | E55: 0
A56: apy_paper_random_igra_3hp | B56: random | C56: costs | D56: tbDiseaseCostsAverted | E56: 76318.4
A57: apy_paper_random_igra_3hp | B57: random | C57: costs | D57: baselineTBDiseaseCost | E57: 705945.2
A58: apy_paper_random_igra_3hp | B58: random | C58: costs | D58: interventionTBDiseaseCost | E58: 629626.8
A59: apy_paper_random_igra_3hp | B59: random | C59: costs | D59: totalProgramCost | E59: 56362.23
A60: apy_paper_random_igra_3hp | B60: random | C60: costs | D60: netCostVsBaseline | E60: -19956.17
A61: apy_paper_ltbi_igra_3hp | B61: ltbi | C61: costs | D61: testingCost | E61: 51066
A62: apy_paper_ltbi_igra_3hp | B62: ltbi | C62: costs | D62: treatmentCost | E62: 11088.982
... A90: apy_paper_prevent_igra_3hp | B90: prevent | C90: costs | D90: netCostVsBaseline | E90: -167627.75
A93: Sensitivity
A94: scenario_id | B94: screeningStrategy | C94: sensitivity | D94: tbCasesPrevented | E94: dalysAverted | F94: qalysGained | G94: costPerDALYAverted | H94: costPerQALYGained | I94: nmbDALY_45000 | J94: nmbDALY_75000 | K94: nmbQALY_45000 | L94: nmbQALY_75000 | M94: notes
A95: apy_paper_random_igra_3hp | B95: random | C95: no_ltbi_treatment_utility_decrement | D95: 4 | E95: 6.586 | F95: 0.11010795 | G95: -3030.0895 | H95: -181241.87 | I95: 316326.17 | J95: 513906.17 | K95: 24911.027 | L95: 28214.265 | M95: Sensitivity assumption; not a final policy setting.
A96: apy_paper_random_igra_3hp | B96: random | C96: ltbi_treatment_decrement_0_0133 | D96: 4 | E96: 6.586 | F96: 0.0037079452 | G96: -3030.0895 | H96: -5382002.3 | I96: 316326.17 | J96: 513906.17 | K96: 20123.027 | L96: 20234.265 | M96: Sensitivity assumption; not a final policy setting.
...

Sheet Economic_Calculations
A1: Strategy | B1: testType | C1: regimen | D1: N | E1: nReps | F1: screenCoverage | G1: screenWindow | H1: followHorizon | I1: nScreened | J1: nTotalCoursesStarted | K1: nTotalCoursesCompleted | L1: nFalsePositiveTreated | M1: nCuredInfection | N1: nPreventedActiveTB | O1: nActiveBy20y_DoNothing | P1: nActiveBy20y_AfterStrategy | Q1: relativeReduction20y | R1: testingCost | S1: treatmentCost | T1: falsePositiveIncrementalCost | U1: programmeSetupCost | V1: programmeRunningCost | W1: returnForResultsCost | X1: clinicReviewCost | Y1: activeTBExclusionCost | Z1: travelOutreachSupportCost | AA1: totalProgramCost | AB1: tbDiseaseCostsAverted | AC1: baselineTBDiseaseCost | AD1: interventionTBDiseaseCost | AE1: netCostVsBaseline | AF1: costPerPersonScreened | AG1: costPerTPTCourseStarted | AH1: costPerTPTCourseCompleted | AI1: costPerInfectionCured | AJ1: costPerTBCasePrevented | AK1: tbDeathsPrevented | AL1: yldAverted | AM1: yllAverted | AN1: dalysAverted | AO1: morbidityOnlyQALYsGained | AP1: treatmentDecrementQALYLoss | AQ1: saeQALYLoss | AR1: qalysGained | AS1: costPerDALYAverted | AT1: costPerQALYGained | AU1: nmbDALY_45000 | AV1: nmbDALY_75000 | AW1: nmbQALY_45000 | AX1: nmbQALY_75000 | AY1: breakEvenTBCasesPrevented | AZ1: additionalCostMarginBeforeNotCostSaving | BA1: additionalCostPerScreenedBeforeNotCostSaving | BB1: additionalCostPerTPTStartBeforeNotCostSaving
A2: Random | B2: =Model_Outputs!C3 -> IGRA | C2: =Model_Outputs!D3 -> 3HP | D2: =Model_Outputs!E3 -> 1500 | E2: =Model_Outputs!F3 -> 2000 | F2: =Model_Outputs!G3 -> 0.3 | G2: =Model_Outputs!H3 -> 2 | H2: =Model_Outputs!I3 -> 20 | I2: =Model_Outputs!J3 -> 450 | ... Q2: =Model_Outputs!R3 -> 0.10526316 | R2: =IFERROR(I2*IF(B2="IGRA",Inputs_Assumptions!$B$2,Inputs_Assumptions!$B$3),"") -> 51066 | S2: =IFERROR(J2*IF(C2="3HP",Inputs_Assumptions!$B$4,IF(C2="4R",Inputs_Assumptions!$B$5,0)),"") -> 5296.2304 | T2: =IFERROR(L2*Inputs_Assumptions!$B$9,"") -> 0 | U2: =Inputs_Assumptions!$B$7 -> 1000000 | V2: =Inputs_Assumptions!$B$8 -> 0 | W2: =IFERROR(I2*Inputs_Assumptions!$B$10,"") -> 0 | X2: =IFERROR(J2*Inputs_Assumptions!$B$11,"") -> 0 | Y2: =IFERROR(J2*Inputs_Assumptions!$B$12,"") -> 0 | Z2: =IFERROR(I2*Inputs_Assumptions!$B$13,"") -> 0 | AA2: =SUM(R2:Z2) -> 1056362.2 | AB2: =IFERROR(N2*Inputs_Assumptions!$B$6,"") -> 76318.4 | AC2: =IFERROR(O2*Inputs_Assumptions!$B$6,"") -> 705945.2 | AD2: =IFERROR(P2*Inputs_Assumptions!$B$6,"") -> 629626.8 | AE2: =IFERROR(AA2-AB2,"") -> 980043.83 | AF2: =IFERROR(AA2/I2,"") -> 2347.4716 | AG2: =IFERROR(AA2/J2,"") -> 33011.32 | AH2: =IFERROR(AA2/K2,"") -> 42254.489 | AI2: =IFERROR(AE2/M2,"") -> 61252.739 | AJ2: =IFERROR(AE2/N2,"") -> 245010.96 | AK2: =IFERROR(N2*Inputs_Assumptions!$B$16,"") -> 0.296 | AL2: =IFERROR(N2*Inputs_Assumptions!$B$14*Inputs_Assumptions!$B$15,"") -> 0.666 | AM2: =IFERROR(AK2*Inputs_Assumptions!$B$17,"") -> 5.92 | AN2: =IFERROR(AL2+AM2,"") -> 6.586 | AO2: =IFERROR(N2*(Inputs_Assumptions!$B$18-Inputs_Assumptions!$B$19)*Inputs_Assumptions!$B$15,"") -> 0.1102 | AP2: =IFERROR(J2*Inputs_Assumptions!$B$22*IF(C2="3HP",0.25,IF(C2="4R",4/12,0)),"") -> 0 | AQ2: =0 -> 0 | AR2: =IFERROR(AO2-AP2-AQ2,"") -> 0.1102 | AS2: =IFERROR(AE2/AN2,"") -> 148807.14 | AT2: =IFERROR(AE2/AR2,"") -> 8893319.7 | AU2: =IFERROR(AN2*Inputs_Assumptions!$B$23-AE2,"") -> -683673.83 | AV2: =IFERROR(AN2*Inputs_Assumptions!$B$24-AE2,"") -> -486093.83 | AW2: =IFERROR(AR2*Inputs_Assumptions!$B$23-AE2,"") -> -975084.83 | AX2: =IFERROR(AR2*Inputs_Assumptions!$B$24-AE2,"") -> -971778.83 | AY2: =IFERROR(AA2/Inputs_Assumptions!$B$6,"") -> 55.366057 | AZ2: =IFERROR(IF(AE2<0,-AE2,0),"") -> 0 | BA2: =IFERROR(AY2/I2,"") -> 0.12303568 | BB2: =IFERROR(AY2/J2,"") -> 1.7301893
A3: LTBI-targeted | B3: =Model_Outputs!C4 -> IGRA | C3: =Model_Outputs!D4 -> 3HP | D3: =Model_Outputs!E4 -> 1500 | E3: =Model_Outputs!F4 -> 2000 | F3: =Model_Outputs!G4 -> 0.3 | G3: =Model_Outputs!H4 -> 2 | H3: =Model_Outputs!I4 -> 20 | I3: =Model_Outputs!J4 -> 450 | ... Q3: =Model_Outputs!R4 -> 0.30434783 | R3: =IFERROR(I3*IF(B3="IGRA",Inputs_Assumptions!$B$2,Inputs_Assumptions!$B$3),"") -> 51066 | S3: =IFERROR(J3*IF(C3="3HP",Inputs_Assumptions!$B$4,IF(C3="4R",Inputs_Assumptions!$B$5,0)),"") -> 11088.982 | T3: =IFERROR(L3*Inputs_Assumptions!$B$9,"") -> 0 | U3: =Inputs_Assumptions!$B$7 -> 1000000 | V3: =Inputs_Assumptions!$B$8 -> 0 | W3: =IFERROR(I3*Inputs_Assumptions!$B$10,"") -> 0 | X3: =IFERROR(J3*Inputs_Assumptions!$B$11,"") -> 0 | Y3: =IFERROR(J3*Inputs_Assumptions!$B$12,"") -> 0 | Z3: =IFERROR(I3*Inputs_Assumptions!$B$13,"") -> 0 | AA3: =SUM(R3:Z3) -> 1062155 | AB3: =IFERROR(N3*Inputs_Assumptions!$B$6,"") -> 209875.6 | AC3: =IFERROR(O3*Inputs_Assumptions!$B$6,"") -> 705945.2 | AD3: =IFERROR(P3*Inputs_Assumptions!$B$6,"") -> 496069.6 | AE3: =IFERROR(AA3-AB3,"") -> 852279.38 | AF3: =IFERROR(AA3/I3,"") -> 2360.3444 | AG3: =IFERROR(AA3/J3,"") -> 15853.059 | AH3: =IFERROR(AA3/K3,"") -> 19669.537 | AI3: =IFERROR(AE3/M3,"") -> 21306.985 | AJ3: =IFERROR(AE3/N3,"") -> 77479.944 | AK3: =IFERROR(N3*Inputs_Assumptions!$B$16,"") -> 0.814 | AL3: =IFERROR(N3*Inputs_Assumptions!$B$14*Inputs_Assumptions!$B$15,"") -> 1.8315 | AM3: =IFERROR(AK3*Inputs_Assumptions!$B$17,"") -> 16.28 | AN3: =IFERROR(AL3+AM3,"") -> 18.1115 | AO3: =IFERROR(N3*(Inputs_Assumptions!$B$18-Inputs_Assumptions!$B$19)*Inputs_Assumptions!$B$15,"") -> 0.30305 | AP3: =IFERROR(J3*Inputs_Assumptions!$B$22*IF(C3="3HP",0.25,IF(C3="4R",4/12,0)),"") -> 0 | AQ3: =0 -> 0 | AR3: =IFERROR(AO3-AP3-AQ3,"") -> 0.30305 | AS3: =IFERROR(AE3/AN3,"") -> 47057.36 | AT3: =IFERROR(AE3/AR3,"") -> 2812339.2 | AU3: =IFERROR(AN3*Inputs_Assumptions!$B$23-AE3,"") -> -37261.882 | AV3: =IFERROR(AN3*Inputs_Assumptions!$B$24-AE3,"") -> 506083.12 | AW3: =IFERROR(AR3*Inputs_Assumptions!$B$23-AE3,"") -> -838642.13 | AX3: =IFERROR(AR3*Inputs_Assumptions!$B$24-AE3,"") -> -829550.63 | AY3: =IFERROR(AA3/Inputs_Assumptions!$B$6,"") -> 55.669667 | AZ3: =IFERROR(IF(AE3<0,-AE3,0),"") -> 0 | BA3: =IFERROR(AY3/I3,"") -> 0.12371037 | BB3: =IFERROR(AY3/J3,"") -> 0.83089056
A4: Cure-targeted | B4: =Model_Outputs!C5 -> IGRA | C4: =Model_Outputs!D5 -> 3HP | D4: =Model_Outputs!E5 -> 1500 | E4: =Model_Outputs!F5 -> 2000 | F4: =Model_Outputs!G5 -> 0.3 | G4: =Model_Outputs!H5 -> 2 | H4: =Model_Outputs!I5 -> 20 | I4: =Model_Outputs!J5 -> 450 | ... Q4: =Model_Outputs!R5 -> 0.2972973 | R4: =IFERROR(I4*IF(B4="IGRA",Inputs_Assumptions!$B$2,Inputs_Assumptions!$B$3),"") -> 51066 | S4: =IFERROR(J4*IF(C4="3HP",Inputs_Assumptions!$B$4,IF(C4="4R",Inputs_Assumptions!$B$5,0)),"") -> 11088.982 | T4: =IFERROR(L4*Inputs_Assumptions!$B$9,"") -> 0 | U4: =Inputs_Assumptions!$B$7 -> 1000000 | V4: =Inputs_Assumptions!$B$8 -> 0 | W4: =IFERROR(I4*Inputs_Assumptions!$B$10,"") -> 0 | X4: =IFERROR(J4*Inputs_Assumptions!$B$11,"") -> 0 | Y4: =IFERROR(J4*Inputs_Assumptions!$B$12,"") -> 0 | Z4: =IFERROR(I4*Inputs_Assumptions!$B$13,"") -> 0 | AA4: =SUM(R4:Z4) -> 1062155 | AB4: =IFERROR(N4*Inputs_Assumptions!$B$6,"") -> 209875.6 | AC4: =IFERROR(O4*Inputs_Assumptions!$B$6,"") -> 705945.2 | AD4: =IFERROR(P4*Inputs_Assumptions!$B$6,"") -> 496069.6 | AE4: =IFERROR(AA4-AB4,"") -> 852279.38 | AF4: =IFERROR(AA4/I4,"") -> 2360.3444 | AG4: =IFERROR(AA4/J4,"") -> 15853.059 | AH4: =IFERROR(AA4/K4,"") -> 19669.537 | AI4: =IFERROR(AE4/M4,"") -> 21306.985 | AJ4: =IFERROR(AE4/N4,"") -> 77479.944 | AK4: =IFERROR(N4*Inputs_Assumptions!$B$16,"") -> 0.814 | AL4: =IFERROR(N4*Inputs_Assumptions!$B$14*Inputs_Assumptions!$B$15,"") -> 1.8315 | AM4: =IFERROR(AK4*Inputs_Assumptions!$B$17,"") -> 16.28 | AN4: =IFERROR(AL4+AM4,"") -> 18.1115 | AO4: =IFERROR(N4*(Inputs_Assumptions!$B$18-Inputs_Assumptions!$B$19)*Inputs_Assumptions!$B$15,"") -> 0.30305 | AP4: =IFERROR(J4*Inputs_Assumptions!$B$22*IF(C4="3HP",0.25,IF(C4="4R",4/12,0)),"") -> 0 | AQ4: =0 -> 0 | AR4: =IFERROR(AO4-AP4-AQ4,"") -> 0.30305 | AS4: =IFERROR(AE4/AN4,"") -> 47057.36 | AT4: =IFERROR(AE4/AR4,"") -> 2812339.2 | AU4: =IFERROR(AN4*Inputs_Assumptions!$B$23-AE4,"") -> -37261.882 | AV4: =IFERROR(AN4*Inputs_Assumptions!$B$24-AE4,"") -> 506083.12 | AW4: =IFERROR(AR4*Inputs_Assumptions!$B$23-AE4,"") -> -838642.13 | AX4: =IFERROR(AR4*Inputs_Assumptions!$B$24-AE4,"") -> -829550.63 | AY4: =IFERROR(AA4/Inputs_Assumptions!$B$6,"") -> 55.669667 | AZ4: =IFERROR(IF(AE4<0,-AE4,0),"") -> 0 | BA4: =IFERROR(AY4/I4,"") -> 0.12371037 | BB4: =IFERROR(AY4/J4,"") -> 0.83089056
A5: Prevention-targeted | B5: =Model_Outputs!C6 -> IGRA | C5: =Model_Outputs!D6 -> 3HP | D5: =Model_Outputs!E6 -> 1500 | E5: =Model_Outputs!F6 -> 2000 | F5: =Model_Outputs!G6 -> 0.3 | G5: =Model_Outputs!H6 -> 2 | H5: =Model_Outputs!I6 -> 20 | I5: =Model_Outputs!J6 -> 450 | ... Q5: =Model_Outputs!R6 -> 0.32352941 | R5: =IFERROR(I5*IF(B5="IGRA",Inputs_Assumptions!$B$2,Inputs_Assumptions!$B$3),"") -> 51066 | S5: =IFERROR(J5*IF(C5="3HP",Inputs_Assumptions!$B$4,IF(C5="4R",Inputs_Assumptions!$B$5,0)),"") -> 10261.446 | T5: =IFERROR(L5*Inputs_Assumptions!$B$9,"") -> 0 | U5: =Inputs_Assumptions!$B$7 -> 1000000 | V5: =Inputs_Assumptions!$B$8 -> 0 | W5: =IFERROR(I5*Inputs_Assumptions!$B$10,"") -> 0 | X5: =IFERROR(J5*Inputs_Assumptions!$B$11,"") -> 0 | Y5: =IFERROR(J5*Inputs_Assumptions!$B$12,"") -> 0 | Z5: =IFERROR(I5*Inputs_Assumptions!$B$13,"") -> 0 | AA5: =SUM(R5:Z5) -> 1061327.4 | AB5: =IFERROR(N5*Inputs_Assumptions!$B$6,"") -> 228955.2 | AC5: =IFERROR(O5*Inputs_Assumptions!$B$6,"") -> 705945.2 | AD5: =IFERROR(P5*Inputs_Assumptions!$B$6,"") -> 476990 | AE5: =IFERROR(AA5-AB5,"") -> 832372.25 | AF5: =IFERROR(AA5/I5,"") -> 2358.5054 | AG5: =IFERROR(AA5/J5,"") -> 17118.185 | AH5: =IFERROR(AA5/K5,"") -> 21226.549 | AI5: =IFERROR(AE5/M5,"") -> 22496.547 | AJ5: =IFERROR(AE5/N5,"") -> 69364.354 | AK5: =IFERROR(N5*Inputs_Assumptions!$B$16,"") -> 0.888 | AL5: =IFERROR(N5*Inputs_Assumptions!$B$14*Inputs_Assumptions!$B$15,"") -> 1.998 | AM5: =IFERROR(AK5*Inputs_Assumptions!$B$17,"") -> 17.76 | AN5: =IFERROR(AL5+AM5,"") -> 19.758 | AO5: =IFERROR(N5*(Inputs_Assumptions!$B$18-Inputs_Assumptions!$B$19)*Inputs_Assumptions!$B$15,"") -> 0.3306 | AP5: =IFERROR(J5*Inputs_Assumptions!$B$22*IF(C5="3HP",0.25,IF(C5="4R",4/12,0)),"") -> 0 | AQ5: =0 -> 0 | AR5: =IFERROR(AO5-AP5-AQ5,"") -> 0.3306 | AS5: =IFERROR(AE5/AN5,"") -> 42128.366 | AT5: =IFERROR(AE5/AR5,"") -> 2517762.4 | AU5: =IFERROR(AN5*Inputs_Assumptions!$B$23-AE5,"") -> 56737.754 | AV5: =IFERROR(AN5*Inputs_Assumptions!$B$24-AE5,"") -> 649477.75 | AW5: =IFERROR(AR5*Inputs_Assumptions!$B$23-AE5,"") -> -817495.25 | AX5: =IFERROR(AR5*Inputs_Assumptions!$B$24-AE5,"") -> -807577.25 | AY5: =IFERROR(AA5/Inputs_Assumptions!$B$6,"") -> 55.626294 | AZ5: =IFERROR(IF(AE5<0,-AE5,0),"") -> 0 | BA5: =IFERROR(AY5/I5,"") -> 0.12361399 | BB5: =IFERROR(AY5/J5,"") -> 0.8971983

Sheet Strategy_Summary
A1: Strategy | B1: TB cases prevented | C1: Net cost vs baseline | D1: DALYs averted | E1: QALYs gained | F1: Cost per DALY averted | G1: Cost per QALY gained | H1: Cost per active TB case prevented | I1: NMB at AUD 45,000/QALY | J1: NMB at AUD 75,000/QALY | K1: Additional cost margin before not cost-saving | L1: Additional cost per screened person before not cost-saving
A2: =Economic_Calculations!A2 -> Random | B2: =Economic_Calculations!N2 -> 4 | C2: =Economic_Calculations!AE2 -> 980043.83 | D2: =Economic_Calculations!AN2 -> 6.586 | E2: =Economic_Calculations!AR2 -> 0.1102 | F2: =Economic_Calculations!AS2 -> 148807.14 | G2: =Economic_Calculations!AT2 -> 8893319.7 | H2: =Economic_Calculations!AJ2 -> 245010.96 | I2: =Economic_Calculations!AW2 -> -975084.83 | J2: =Economic_Calculations!AX2 -> -971778.83 | K2: =Economic_Calculations!AY2 -> 55.366057 | L2: =Economic_Calculations!AZ2 -> 0
A3: =Economic_Calculations!A3 -> LTBI-targeted | B3: =Economic_Calculations!N3 -> 11 | C3: =Economic_Calculations!AE3 -> 852279.38 | D3: =Economic_Calculations!AN3 -> 18.1115 | E3: =Economic_Calculations!AR3 -> 0.30305 | F3: =Economic_Calculations!AS3 -> 47057.36 | G3: =Economic_Calculations!AT3 -> 2812339.2 | H3: =Economic_Calculations!AJ3 -> 77479.944 | I3: =Economic_Calculations!AW3 -> -838642.13 | J3: =Economic_Calculations!AX3 -> -829550.63 | K3: =Economic_Calculations!AY3 -> 55.669667 | L3: =Economic_Calculations!AZ3 -> 0
A4: =Economic_Calculations!A4 -> Cure-targeted | B4: =Economic_Calculations!N4 -> 11 | C4: =Economic_Calculations!AE4 -> 852279.38 | D4: =Economic_Calculations!AN4 -> 18.1115 | E4: =Economic_Calculations!AR4 -> 0.30305 | F4: =Economic_Calculations!AS4 -> 47057.36 | G4: =Economic_Calculations!AT4 -> 2812339.2 | H4: =Economic_Calculations!AJ4 -> 77479.944 | I4: =Economic_Calculations!AW4 -> -838642.13 | J4: =Economic_Calculations!AX4 -> -829550.63 | K4: =Economic_Calculations!AY4 -> 55.669667 | L4: =Economic_Calculations!AZ4 -> 0
A5: =Economic_Calculations!A5 -> Prevention-targeted | B5: =Economic_Calculations!N5 -> 12 | C5: =Economic_Calculations!AE5 -> 832372.25 | D5: =Economic_Calculations!AN5 -> 19.758 | E5: =Economic_Calculations!AR5 -> 0.3306 | F5: =Economic_Calculations!AS5 -> 42128.366 | G5: =Economic_Calculations!AT5 -> 2517762.4 | H5: =Economic_Calculations!AJ5 -> 69364.354 | I5: =Economic_Calculations!AW5 -> -817495.25 | J5: =Economic_Calculations!AX5 -> -807577.25 | K5: =Economic_Calculations!AY5 -> 55.626294 | L5: =Economic_Calculations!AZ5 -> 0

Sheet Cost_Saving_Check
A1: Strategy | B1: Cases prevented | C1: TB disease cost averted | D1: Included programme cost | E1: Testing cost | F1: Treatment cost | G1: Programme setup/running cost | H1: False-positive incremental cost | I1: Net cost vs baseline | J1: Break-even TB cases prevented | K1: Actual minus break-even cases | L1: Cost-saving yes/no | M1: Notes
A2: =Economic_Calculations!A2 -> Random | B2: =Economic_Calculations!N2 -> 4 | C2: =Economic_Calculations!AB2 -> 76318.4 | D2: =Economic_Calculations!AA2 -> 1056362.2 | E2: =Economic_Calculations!R2 -> 51066 | F2: =Economic_Calculations!S2 -> 5296.2304 | G2: =Economic_Calculations!U2+Economic_Calculations!V2 -> 1000000 | H2: =Economic_Calculations!T2 -> 0 | I2: =Economic_Calculations!AE2 -> 980043.83 | J2: =Economic_Calculations!AX2 -> -971778.83 | K2: =B2-J2 -> 971782.83 | L2: =IF(I2<0,"yes","no") -> no | M2: Updates from Inputs_Assumptions; APY model outputs require rerun.
A3: =Economic_Calculations!A3 -> LTBI-targeted | B3: =Economic_Calculations!N3 -> 11 | C3: =Economic_Calculations!AB3 -> 209875.6 | D3: =Economic_Calculations!AA3 -> 1062155 | E3: =Economic_Calculations!R3 -> 51066 | F3: =Economic_Calculations!S3 -> 11088.982 | G3: =Economic_Calculations!U3+Economic_Calculations!V3 -> 1000000 | H3: =Economic_Calculations!T3 -> 0 | I3: =Economic_Calculations!AE3 -> 852279.38 | J3: =Economic_Calculations!AX3 -> -829550.63 | K3: =B3-J3 -> 829561.63 | L3: =IF(I3<0,"yes","no") -> no | M3: Updates from Inputs_Assumptions; APY model outputs require rerun.
A4: =Economic_Calculations!A4 -> Cure-targeted | B4: =Economic_Calculations!N4 -> 11 | C4: =Economic_Calculations!AB4 -> 209875.6 | D4: =Economic_Calculations!AA4 -> 1062155 | E4: =Economic_Calculations!R4 -> 51066 | F4: =Economic_Calculations!S4 -> 11088.982 | G4: =Economic_Calculations!U4+Economic_Calculations!V4 -> 1000000 | H4: =Economic_Calculations!T4 -> 0 | I4: =Economic_Calculations!AE4 -> 852279.38 | J4: =Economic_Calculations!AX4 -> -829550.63 | K4: =B4-J4 -> 829561.63 | L4: =IF(I4<0,"yes","no") -> no | M4: Updates from Inputs_Assumptions; APY model outputs require rerun.
A5: =Economic_Calculations!A5 -> Prevention-targeted | B5: =Economic_Calculations!N5 -> 12 | C5: =Economic_Calculations!AB5 -> 228955.2 | D5: =Economic_Calculations!AA5 -> 1061327.4 | E5: =Economic_Calculations!R5 -> 51066 | F5: =Economic_Calculations!S5 -> 10261.446 | G5: =Economic_Calculations!U5+Economic_Calculations!V5 -> 1000000 | H5: =Economic_Calculations!T5 -> 0 | I5: =Economic_Calculations!AE5 -> 832372.25 | J5: =Economic_Calculations!AX5 -> -807577.25 | K5: =B5-J5 -> 807589.25 | L5: =IF(I5<0,"yes","no") -> no | M5: Updates from Inputs_Assumptions; APY model outputs require rerun.

Sheet Decision_Tree
A1: Strategy | B1: Stage | C1: Branch | D1: Probability / rate | E1: Count | F1: Cost per person | G1: Total cost | H1: Utility / disability input | I1: Health outcome | J1: Notes
A2: =Economic_Calculations!A2 -> Random | B2: Eligible cohort | C2: All | D2: =1 -> 1 | E2: =Economic_Calculations!D2 -> 1500 | J2: Imported model N.
A3: =Economic_Calculations!A2 -> Random | B3: Screened | C3: Screened within window | D3: =IFERROR(Economic_Calculations!I2/Economic_Calculations!D2,"") -> 0.3 | E3: =Economic_Calculations!I2 -> 450 | F3: =IFERROR(Economic_Calculations!R2/Economic_Calculations!I2,"") -> 113.48 | G3: =Economic_Calculations!R2 -> 51066 | J3: Model output count; cost formula-linked.
A4: =Economic_Calculations!A2 -> Random | B4: TPT started | C4: Started preventive treatment | D4: =IFERROR(Economic_Calculations!J2/Economic_Calculations!I2,"") -> 0.071111111 | E4: =Economic_Calculations!J2 -> 32 | F4: =IFERROR(Economic_Calculations!S2/Economic_Calculations!J2,"") -> 165.5072 | G4: =Economic_Calculations!S2 -> 5296.2304 | H4: LTBI treatment decrement | J4: Model output count; cost formula-linked.
A5: =Economic_Calculations!A2 -> Random | B5: TPT completed | C5: Completed course | D5: =IFERROR(Economic_Calculations!K2/Economic_Calculations!J2,"") -> 0.78125 | E5: =Economic_Calculations!K2 -> 25 | J5: Model output count.
A6: =Economic_Calculations!A2 -> Random | B6: False positive treated | C6: False-positive TPT | D6: =IFERROR(Economic_Calculations!L2/Economic_Calculations!J2,"") -> 0.21875 | E6: =Economic_Calculations!L2 -> 7 | F6: =Inputs_Assumptions!$B$9 -> 0 | G6: =Economic_Calculations!T2 -> 0 | J6: False-positive incremental cost unresolved.
A7: =Economic_Calculations!A2 -> Random | B7: Infection cured/protected | C7: Cured/protected | D7: =IFERROR(Economic_Calculations!M2/Economic_Calculations!J2,"") -> 0.5 | E7: =Economic_Calculations!M2 -> 16 | I7: Infections cured/protected | J7: Model output.
A8: =Economic_Calculations!A2 -> Random | B8: Active TB case prevented | C8: Direct person-level case | D8: =IFERROR(Economic_Calculations!N2/Economic_Calculations!D2,"") -> 0.0026666667 | E8: =Economic_Calculations!N2 -> 4 | F8: =Inputs_Assumptions!$B$6 -> 19079.6 | G8: =Economic_Calculations!AB2 -> 76318.4 | H8: DW/CFR/YLL assumptions | I8: DALYs/QALYs | J8: No downstream transmission benefit included.
A9: =Economic_Calculations!A2 -> Random | B9: DALYs averted | C9: Health outcome | H9: DW, duration, CFR, YLL | I9: =Economic_Calculations!AN2 -> 6.586 | J9: Formula-linked.
A10: =Economic_Calculations!A2 -> Random | B10: QALYs gained | C10: Health outcome | H10: Utility assumptions | I10: =Economic_Calculations!AR2 -> 0.1102 | J10: Formula-linked.
A11: =Economic_Calculations!A2 -> Random | B11: Net cost | C11: Economic outcome | G11: =Economic_Calculations!AE2 -> 980043.83 | J11: Negative means cost-saving.
A12: =Economic_Calculations!A2 -> Random | B12: ICER per DALY | C12: Economic outcome | I12: =Economic_Calculations!AS2 -> 148807.14 | J12: Formula-linked.
A13: =Economic_Calculations!A2 -> Random | B13: ICER per QALY | C13: Economic outcome | I13: =Economic_Calculations!AT2 -> 8893319.7 | J13: Formula-linked.
A14: =Economic_Calculations!A3 -> LTBI-targeted | B14: Eligible cohort | C14: All | D14: =1 -> 1 | E14: =Economic_Calculations!D3 -> 1500 | J14: Imported model N.
A15: =Economic_Calculations!A3 -> LTBI-targeted | B15: Screened | C15: Screened within window | D15: =IFERROR(Economic_Calculations!I3/Economic_Calculations!D3,"") -> 0.3 | E15: =Economic_Calculations!I3 -> 450 | F15: =IFERROR(Economic_Calculations!R3/Economic_Calculations!I3,"") -> 113.48 | G15: =Economic_Calculations!R3 -> 51066 | J15: Model output count; cost formula-linked.
A16: =Economic_Calculations!A3 -> LTBI-targeted | B16: TPT started | C16: Started preventive treatment | D16: =IFERROR(Economic_Calculations!J3/Economic_Calculations!I3,"") -> 0.14888889 | E16: =Economic_Calculations!J3 -> 67 | F16: =IFERROR(Economic_Calculations!S3/Economic_Calculations!J3,"") -> 165.5072 | G16: =Economic_Calculations!S3 -> 11088.982 | H16: LTBI treatment decrement | J16: Model output count; cost formula-linked.
A17: =Economic_Calculations!A3 -> LTBI-targeted | B17: TPT completed | C17: Completed course | D17: =IFERROR(Economic_Calculations!K3/Economic_Calculations!J3,"") -> 0.80597015 | E17: =Economic_Calculations!K3 -> 54 | J17: Model output count.
A18: =Economic_Calculations!A3 -> LTBI-targeted | B18: False positive treated | C18: False-positive TPT | D18: =IFERROR(Economic_Calculations!L3/Economic_Calculations!J3,"") -> 0.089552239 | E18: =Economic_Calculations!L3 -> 6 | F18: =Inputs_Assumptions!$B$9 -> 0 | G18: =Economic_Calculations!T3 -> 0 | J18: False-positive incremental cost unresolved.
A19: =Economic_Calculations!A3 -> LTBI-targeted | B19: Infection cured/protected | C19: Cured/protected | D19: =IFERROR(Economic_Calculations!M3/Economic_Calculations!J3,"") -> 0.59701493 | E19: =Economic_Calculations!M3 -> 40 | I19: Infections cured/protected | J19: Model output.
A20: =Economic_Calculations!A3 -> LTBI-targeted | B20: Active TB case prevented | C20: Direct person-level case | D20: =IFERROR(Economic_Calculations!N3/Economic_Calculations!D3,"") -> 0.0073333333 | E20: =Economic_Calculations!N3 -> 11 | F20: =Inputs_Assumptions!$B$6 -> 19079.6 | G20: =Economic_Calculations!AB3 -> 209875.6 | H20: DW/CFR/YLL assumptions | I20: DALYs/QALYs | J20: No downstream transmission benefit included.
A21: =Economic_Calculations!A3 -> LTBI-targeted | B21: DALYs averted | C21: Health outcome | H21: DW, duration, CFR, YLL | I21: =Economic_Calculations!AN3 -> 18.1115 | J21: Formula-linked.
A22: =Economic_Calculations!A3 -> LTBI-targeted | B22: QALYs gained | C22: Health outcome | H22: Utility assumptions | I22: =Economic_Calculations!AR3 -> 0.30305 | J22: Formula-linked.
A23: =Economic_Calculations!A3 -> LTBI-targeted | B23: Net cost | C23: Economic outcome | G23: =Economic_Calculations!AE3 -> 852279.38 | J23: Negative means cost-saving.
A24: =Economic_Calculations!A3 -> LTBI-targeted | B24: ICER per DALY | C24: Economic outcome | I24: =Economic_Calculations!AS3 -> 47057.36 | J24: Formula-linked.
A25: =Economic_Calculations!A3 -> LTBI-targeted | B25: ICER per QALY | C25: Economic outcome | I25: =Economic_Calculations!AT3 -> 2812339.2 | J25: Formula-linked.
A26: =Economic_Calculations!A4 -> Cure-targeted | B26: Eligible cohort | C26: All | D26: =1 -> 1 | E26: =Economic_Calculations!D4 -> 1500 | J26: Imported model N.
A27: =Economic_Calculations!A4 -> Cure-targeted | B27: Screened | C27: Screened within window | D27: =IFERROR(Economic_Calculations!I4/Economic_Calculations!D4,"") -> 0.3 | E27: =Economic_Calculations!I4 -> 450 | F27: =IFERROR(Economic_Calculations!R4/Economic_Calculations!I4,"") -> 113.48 | G27: =Economic_Calculations!R4 -> 51066 | J27: Model output count; cost formula-linked.
A28: =Economic_Calculations!A4 -> Cure-targeted | B28: TPT started | C28: Started preventive treatment | D28: =IFERROR(Economic_Calculations!J4/Economic_Calculations!I4,"") -> 0.14888889 | E28: =Economic_Calculations!J4 -> 67 | F28: =IFERROR(Economic_Calculations!S4/Economic_Calculations!J4,"") -> 165.5072 | G28: =Economic_Calculations!S4 -> 11088.982 | H28: LTBI treatment decrement | J28: Model output count; cost formula-linked.
A29: =Economic_Calculations!A4 -> Cure-targeted | B29: TPT completed | C29: Completed course | D29: =IFERROR(Economic_Calculations!K4/Economic_Calculations!J4,"") -> 0.80597015 | E29: =Economic_Calculations!K4 -> 54 | J29: Model output count.
A30: =Economic_Calculations!A4 -> Cure-targeted | B30: False positive treated | C30: False-positive TPT | D30: =IFERROR(Economic_Calculations!L4/Economic_Calculations!J4,"") -> 0.089552239 | E30: =Economic_Calculations!L4 -> 6 | F30: =Inputs_Assumptions!$B$9 -> 0 | G30: =Economic_Calculations!T4 -> 0 | J30: False-positive incremental cost unresolved.
A31: =Economic_Calculations!A4 -> Cure-targeted | B31: Infection cured/protected | C31: Cured/protected | D31: =IFERROR(Economic_Calculations!M4/Economic_Calculations!J4,"") -> 0.59701493 | E31: =Economic_Calculations!M4 -> 40 | I31: Infections cured/protected | J31: Model output.
A32: =Economic_Calculations!A4 -> Cure-targeted | B32: Active TB case prevented | C32: Direct person-level case | D32: =IFERROR(Economic_Calculations!N4/Economic_Calculations!D4,"") -> 0.0073333333 | E32: =Economic_Calculations!N4 -> 11 | F32: =Inputs_Assumptions!$B$6 -> 19079.6 | G32: =Economic_Calculations!AB4 -> 209875.6 | H32: DW/CFR/YLL assumptions | I32: DALYs/QALYs | J32: No downstream transmission benefit included.
A33: =Economic_Calculations!A4 -> Cure-targeted | B33: DALYs averted | C33: Health outcome | H33: DW, duration, CFR, YLL | I33: =Economic_Calculations!AN4 -> 18.1115 | J33: Formula-linked.
A34: =Economic_Calculations!A4 -> Cure-targeted | B34: QALYs gained | C34: Health outcome | H34: Utility assumptions | I34: =Economic_Calculations!AR4 -> 0.30305 | J34: Formula-linked.
A35: =Economic_Calculations!A4 -> Cure-targeted | B35: Net cost | C35: Economic outcome | G35: =Economic_Calculations!AE4 -> 852279.38 | J35: Negative means cost-saving.
A36: =Economic_Calculations!A4 -> Cure-targeted | B36: ICER per DALY | C36: Economic outcome | I36: =Economic_Calculations!AS4 -> 47057.36 | J36: Formula-linked.
A37: =Economic_Calculations!A4 -> Cure-targeted | B37: ICER per QALY | C37: Economic outcome | I37: =Economic_Calculations!AT4 -> 2812339.2 | J37: Formula-linked.
A38: =Economic_Calculations!A5 -> Prevention-targeted | B38: Eligible cohort | C38: All | D38: =1 -> 1 | E38: =Economic_Calculations!D5 -> 1500 | J38: Imported model N.
A39: =Economic_Calculations!A5 -> Prevention-targeted | B39: Screened | C39: Screened within window | D39: =IFERROR(Economic_Calculations!I5/Economic_Calculations!D5,"") -> 0.3 | E39: =Economic_Calculations!I5 -> 450 | F39: =IFERROR(Economic_Calculations!R5/Economic_Calculations!I5,"") -> 113.48 | G39: =Economic_Calculations!R5 -> 51066 | J39: Model output count; cost formula-linked.
A40: =Economic_Calculations!A5 -> Prevention-targeted | B40: TPT started | C40: Started preventive treatment | D40: =IFERROR(Economic_Calculations!J5/Economic_Calculations!I5,"") -> 0.13777778 | E40: =Economic_Calculations!J5 -> 62 | F40: =IFERROR(Economic_Calculations!S5/Economic_Calculations!J5,"") -> 165.5072 | G40: =Economic_Calculations!S5 -> 10261.446 | H40: LTBI treatment decrement | J40: Model output count; cost formula-linked.
...

Sheet Sensitivity
A1: scenario_id | B1: screeningStrategy | C1: sensitivity | D1: tbCasesPrevented | E1: dalysAverted | F1: qalysGained | G1: costPerDALYAverted | H1: costPerQALYGained | I1: nmbDALY_45000 | J1: nmbDALY_75000 | K1: nmbQALY_45000 | L1: nmbQALY_75000 | M1: notes | N1: interpretation_changes
A2: apy_paper_random_igra_3hp | B2: random | C2: no_ltbi_treatment_utility_decrement | D2: 4 | E2: 6.586 | F2: 0.11010795 | G2: -3030.0895 | H2: -181241.87 | I2: 316326.17 | J2: 513906.17 | K2: 24911.027 | L2: 28214.265 | M2: Sensitivity assumption; not a final policy setting. | N2: Magnitude changes; generated outputs do not show reversal of preferred strategy.
A3: apy_paper_random_igra_3hp | B3: random | C3: ltbi_treatment_decrement_0_0133 | D3: 4 | E3: 6.586 | F3: 0.0037079452 | G3: -3030.0895 | H3: -5382002.3 | I3: 316326.17 | J3: 513906.17 | K3: 20123.027 | L3: 20234.265 | M3: Sensitivity assumption; not a final policy setting. | N3: Magnitude changes; generated outputs do not show reversal of preferred strategy.
A4: apy_paper_random_igra_3hp | B4: random | C4: yld_only_no_yll | D4: 4 | E4: 0.666 | F4: 0.11010795 | G4: -29964.219 | H4: -181241.87 | I4: 49926.17 | J4: 69906.17 | K4: 24911.027 | L4: 28214.265 | M4: Sensitivity assumption; not a final policy setting. | N4: Magnitude changes; generated outputs do not show reversal of preferred strategy.
A5: apy_paper_random_igra_3hp | B5: random | C5: conservative_yll_10 | D5: 4 | E5: 3.626 | F5: 0.11010795 | G5: -5503.632 | H5: -181241.87 | I5: 183126.17 | J5: 291906.17 | K5: 24911.027 | L5: 28214.265 | M5: Sensitivity assumption; not a final policy setting. | N5: Magnitude changes; generated outputs do not show reversal of preferred strategy.
A6: apy_paper_random_igra_3hp | B6: random | C6: higher_yll_30 | D6: 4 | E6: 9.546 | F6: 0.11010795 | G6: -2090.5269 | H6: -181241.87 | I6: 449526.17 | J6: 735906.17 | K6: 24911.027 | L6: 28214.265 | M6: Sensitivity assumption; not a final policy setting. | N6: Magnitude changes; generated outputs do not show reversal of preferred strategy.
A7: apy_paper_random_igra_3hp | B7: random | C7: lower_tb_case_fatality | D7: 4 | E7: 3.626 | F7: 0.11010795 | G7: -5503.632 | H7: -181241.87 | I7: 183126.17 | J7: 291906.17 | K7: 24911.027 | L7: 28214.265 | M7: Sensitivity assumption; not a final policy setting. | N7: Magnitude changes; generated outputs do not show reversal of preferred strategy.
A8: apy_paper_random_igra_3hp | B8: random | C8: higher_tb_case_fatality | D8: 4 | E8: 9.546 | F8: 0.11010795 | G8: -2090.5269 | H8: -181241.87 | I8: 449526.17 | J8: 735906.17 | K8: 24911.027 | L8: 28214.265 | M8: Sensitivity assumption; not a final policy setting. | N8: Magnitude changes; generated outputs do not show reversal of preferred strategy.
A9: apy_paper_ltbi_igra_3hp | B9: ltbi | C9: no_ltbi_treatment_utility_decrement | D9: 11 | E9: 18.1115 | F9: 0.30277384 | G9: -8156.178 | H9: -487890.96 | I9: 962738.12 | J9: 1506083.1 | K9: 161345.44 | L9: 170428.66 | M9: Sensitivity assumption; not a final policy setting. | N9: Magnitude changes; generated outputs do not show reversal of preferred strategy.
A10: apy_paper_ltbi_igra_3hp | B10: ltbi | C10: ltbi_treatment_decrement_0_0133 | D10: 11 | E10: 18.1115 | F10: 0.079998836 | G10: -8156.178 | H10: -1846534.6 | I10: 962738.12 | J10: 1506083.1 | K10: 151320.57 | L10: 153720.53 | M10: Sensitivity assumption; not a final policy setting. | N10: Magnitude changes; generated outputs do not show reversal of preferred strategy.
A11: apy_paper_ltbi_igra_3hp | B11: ltbi | C11: yld_only_no_yll | D11: 11 | E11: 1.8315 | F11: 0.30277384 | G11: -80655.538 | H11: -487890.96 | I11: 230138.12 | J11: 285083.12 | K11: 161345.44 | L11: 170428.66 | M11: Sensitivity assumption; not a final policy setting. | N11: Magnitude changes; generated outputs do not show reversal of preferred strategy.
A12: apy_paper_ltbi_igra_3hp | B12: ltbi | C12: conservative_yll_10 | D12: 11 | E12: 9.9715 | F12: 0.30277384 | G12: -14814.282 | H12: -487890.96 | I12: 596438.12 | J12: 895583.12 | K12: 161345.44 | L12: 170428.66 | M12: Sensitivity assumption; not a final policy setting. | N12: Magnitude changes; generated outputs do not show reversal of preferred strategy.
A13: apy_paper_ltbi_igra_3hp | B13: ltbi | C13: higher_yll_30 | D13: 11 | E13: 26.2515 | F13: 0.30277384 | G13: -5627.1305 | H13: -487890.96 | I13: 1329038.1 | J13: 2116583.1 | K13: 161345.44 | L13: 170428.66 | M13: Sensitivity assumption; not a final policy setting. | N13: Magnitude changes; generated outputs do not show reversal of preferred strategy.
... A29: apy_paper_prevent_igra_3hp | B29: prevent | C29: higher_tb_case_fatality | D29: 12 | E29: 28.638 | F29: 0.33032384 | G29: -5853.3331 | H29: -507464.9 | I29: 1456337.8 | J29: 2315477.8 | K29: 182492.33 | L29: 192402.04 | M29: Sensitivity assumption; not a final policy setting. | N29: Magnitude changes; generated outputs do not show reversal of preferred strategy.

Sheet Chart_Data
A1: Strategy | B1: DALYs averted | C1: QALYs gained | D1: Net cost vs baseline | E1: Cost per DALY averted | F1: Cost per QALY gained | G1: TB cases prevented | H1: Additional cost margin before not cost-saving | I1: Additional cost per screened before not cost-saving | J1: Additional cost per TPT start before not cost-saving
A2: =Strategy_Summary!A2 -> Random | B2: =Strategy_Summary!D2 -> 6.586 | C2: =Strategy_Summary!E2 -> 0.1102 | D2: =Strategy_Summary!C2 -> 980043.83 | E2: =Strategy_Summary!F2 -> 148807.14 | F2: =Strategy_Summary!G2 -> 8893319.7 | G2: =Strategy_Summary!B2 -> 4 | H2: =Strategy_Summary!K2 -> 55.366057 | I2: =Strategy_Summary!L2 -> 0 | J2: =Economic_Calculations!BA2 -> 0.12303568
A3: =Strategy_Summary!A3 -> LTBI-targeted | B3: =Strategy_Summary!D3 -> 18.1115 | C3: =Strategy_Summary!E3 -> 0.30305 | D3: =Strategy_Summary!C3 -> 852279.38 | E3: =Strategy_Summary!F3 -> 47057.36 | F3: =Strategy_Summary!G3 -> 2812339.2 | G3: =Strategy_Summary!B3 -> 11 | H3: =Strategy_Summary!K3 -> 55.669667 | I3: =Strategy_Summary!L3 -> 0 | J3: =Economic_Calculations!BA3 -> 0.12371037
A4: =Strategy_Summary!A4 -> Cure-targeted | B4: =Strategy_Summary!D4 -> 18.1115 | C4: =Strategy_Summary!E4 -> 0.30305 | D4: =Strategy_Summary!C4 -> 852279.38 | E4: =Strategy_Summary!F4 -> 47057.36 | F4: =Strategy_Summary!G4 -> 2812339.2 | G4: =Strategy_Summary!B4 -> 11 | H4: =Strategy_Summary!K4 -> 55.669667 | I4: =Strategy_Summary!L4 -> 0 | J4: =Economic_Calculations!BA4 -> 0.12371037
A5: =Strategy_Summary!A5 -> Prevention-targeted | B5: =Strategy_Summary!D5 -> 19.758 | C5: =Strategy_Summary!E5 -> 0.3306 | D5: =Strategy_Summary!C5 -> 832372.25 | E5: =Strategy_Summary!F5 -> 42128.366 | F5: =Strategy_Summary!G5 -> 2517762.4 | G5: =Strategy_Summary!B5 -> 12 | H5: =Strategy_Summary!K5 -> 55.626294 | I5: =Strategy_Summary!L5 -> 0 | J5: =Economic_Calculations!BA5 -> 0.12361399

Sheet Editable_Charts
A1: Editable native Excel charts. All chart values come from formula-linked Chart_Data ranges.
A2: Open in Excel and allow recalculation before copying charts into Word.

Sheet Formula_Audit
A10: Audit item | B10: Check / source | C10: Notes
A11: Strategy_Summary key cells contain formulas | B11: =_xludf.ISFORMULA(Strategy_Summary!B2) -> #NAME? | C11: Should be TRUE.
A12: Chart_Data key cells contain formulas | B12: =_xludf.ISFORMULA(Chart_Data!B2) -> #NAME? | C12: Should be TRUE.
A13: Editable_Charts sheet contains charts | B13: 6 charts expected | C13: Validated programmatically after save.
A14: No chart series names begin with =Chart_Data | B14: plain text series names for scatter charts | C14: Scatter legends use Random, LTBI-targeted, Cure-targeted, Prevention-targeted.
A15: Scatter chart x/y ranges | B15: DALYs/QALYs as x-values; net cost as y-values | C15: Cost-effectiveness plane charts use Chart_Data columns B/C and D.
A16: Scatter chart markers | B16: visible markers; no connecting lines requested | C16: One one-point marker series per strategy.
A17: Unresolved programme costs still zero | B17: =AND(Inputs_Assumptions!B7=0,Inputs_Assumptions!B8=0,Inputs_Assumptions!B9=0,Inputs_Assumptions!B10=0,Inputs_Assumptions!B11=0,Inputs_Assumptions!B12=0,Inputs_Assumptions!B13=0) -> FALSE | C17: Should be TRUE until local costs are supplied.
A18: Values requiring APY rerun | B18: model output counts and epidemiologic assumptions | C18: Changing screening strategy, prevalence, treatment pathway probabilities, or cases prevented requires rerunning APY and refreshing Model_Outputs.
A19: Values updating directly from Inputs_Assumptions | B19: costs; utilities; DALY/QALY assumptions; WTP thresholds | C19: These update Economic_Calculations, Strategy_Summary, Chart_Data, and charts.
